Workbook

Sheet 说明
A1: 爆破跑道 · 游戏配置表
A3: 怎么用
A4: 1. 修改各工作表里的数值和名称（蓝色字是数值，黑色字是文字，灰色字是 id，不要改 id）。
A5: 2. 每个工作表的第 2 行是游戏读取用的字段名，请不要修改、删除或调换列顺序以外的内容；可以调换列顺序。
A6: 3. 在 Excel 中保存为 .xlsx；如果用 Google Sheets，先把本文件上传到 Google 云端硬盘并用 Google 表格打开，改完后选「文件 → 下载 → Microsoft Excel (.xlsx)」。
A7: 4. 打开游戏页面，点「导入配置表 (.xlsx)」选择文件。游戏会立即按新配置重新开局；有问题的单元格会列在导入提示里，并自动使用默认值。
A8: 5. 点「恢复默认」可以回到内置配置。导入的配置只保存在当前浏览器里，换设备需要重新导入。
A10: 注意
A11: · 说明文字不会随数值自动变化。改了数值（比如冷却秒数），记得同步改对应的说明文字（三种语言）。
A12: · 名称、说明都有中文、English、Français 三列；某一列留空会使用原来的文字。
A13: · 斜体黑字的列（如「累计花费」「本波总人数」）是自动计算的参考列，游戏不读取。
A14: · 「波次」表的行数就是总波数，可以增删行；boss 列填 1 的波次会出现 Boss。
... A36: 数值体检·装置：每个升级和「同价多放几座基础装置」比谁更划算，含估算和实测两套数字

Sheet 全局
A1: 参数 | B1: 数值 | C1: 说明
A2: key | B2: value | C2: desc
A3: waves | B3: 15 | C3: 总波数（须与「波次」表行数一致）
A4: eliteAffixes | B4: 2 | C4: 精英波词缀数量
A5: startGold | B5: 300 | C5: 开局 GST
A6: startLives | B6: 20 | C6: 开局生命
A7: waveReward | B7: 30 | C7: 每波守住的基础 GST 奖励
A8: eliteReward | B8: 60 | C8: 精英波额外 GST 奖励
A9: eliteHpMult | B9: 1.4 | C9: 精英波对手体力倍率
A10: betweenTime | B10: 8 | C10: 两波之间的布置时间（秒）
A11: earlyBonusPerSec | B11: 5 | C11: 提前开波每剩 1 秒奖励的 GST
A12: rerollBase | B12: 20 | C12: 神秘箱重抽起始价格
A13: rerollStep | B13: 10 | C13: 每次重抽涨价
A14: sellRefund | B14: 0.6 | C14: 回收装置返还比例
... A96: scoreClean | B96: 100 | C96: 分数：无漏怪波数权重

Sheet 装置
A1: id | B1: 名称（中文） | C1: 名称（English） | D1: 名称（Français） | E1: 简称（中文） | F1: 简称（English） | G1: 简称（Français） | H1: 说明（中文） | I1: 说明（English） | J1: 说明（Français） | K1: 放置价格 | L1: 效果 | M1: 出手间隔（秒） | N1: 射程（999=全图） | O1: 范围半径 | P1: 减速比例 | Q1: 湿滑持续（秒） | R1: 传播人数 | S1: 传播衰减 | T1: 对耐力跑者效果 | U1: 对 Boss 效果 | V1: 颜色
A2: id | B2: name_zh | C2: name_en | D2: name_fr | E2: short_zh | F2: short_en | G2: short_fr | H2: desc_zh | I2: desc_en | J2: desc_fr | K2: cost | L2: dmg | M2: rate | N2: range | O2: rad | P2: slow | Q2: slowDur | R2: chain | S2: decay | T2: armor | U2: bossMul | V2: color
A3: dart | B3: 易拉罐投手 | C3: Can Thrower | D3: Lanceur de canettes | E3: 易拉罐 | F3: Can | G3: Canette | H3: 单体速投易拉罐；对耐力跑者只有 25% 效果，「铁罐」2 级后破甲 | I3: Rapid single-target cans; only 25% vs endurance runners until “Iron Can” tier 2 | J3: Canettes rapides sur une cible ; 25 % contre les coureurs endurants jusqu’à « Canette en fer » niv. 2 | K3: 100 | L3: 1 | M3: 0.5 | N3: 95 | O3: 0 | P3: 0 | Q3: 0 | R3: 0 | S3: 1 | T3: 0.25 | U3: 0.6 | V3: #ff6b6b
A4: bomb | B4: 香蕉皮投手 | C4: Banana Peeler | D4: Lanceur de peaux de banane | E4: 香蕉皮 | F4: Banana | G4: Banane | H4: 扔香蕉皮，一片跑者一起滑倒；耐力跑者的克星 | I4: Throws banana peels that trip a whole group; counters endurance runners | J4: Lance des peaux de banane qui font glisser un groupe ; contre les endurants | K4: 160 | L4: 3 | M4: 1.3 | N4: 82 | O4: 40 | P4: 0 | Q4: 0 | R4: 0 | S4: 1 | T4: 1 | U4: 1 | V4: #ffd84a
A5: frost | B5: 洒水器 | C5: Sprinkler | D5: Arroseur | E5: 洒水器 | F5: Sprinkler | G5: Arroseur | H5: 洒水让跑道湿滑，范围减速 | I5: Wets the track to slow an area | J5: Mouille la piste pour ralentir une zone | K5: 120 | L5: 0.5 | M5: 1.1 | N5: 72 | O5: 0 | P5: 0.35 | Q5: 1.5 | R5: 0 | S5: 1 | T5: 0.5 | U5: 1 | V5: #6fc3ff
A6: sniper | B6: 鞋盒无人机 | C6: Shoebox Drone | D6: Drone à boîtes | E6: 无人机 | F6: Drone | G6: Drone | H6: 全图空投鞋盒，专砸体力最多的跑者，无视耐力 | I6: Drops shoeboxes anywhere on the strongest runner, ignores endurance | J6: Largue des boîtes partout sur le coureur le plus endurant, ignore l’endurance | K6: 180 | L6: 6 | M6: 1.7 | N6: 999 | O6: 0 | P6: 0 | Q6: 0 | R6: 0 | S6: 1 | T6: 1 | U6: 1 | V6: #ff9d7a
A7: tesla | B7: 广场舞音响 | C7: Dance Speaker | D7: Enceinte de danse | E7: 音响 | F7: Speaker | G7: Enceinte | H7: 洗脑神曲在跑者之间传播，一次影响好几个 | I7: An earworm hops between runners, hitting several at once | J7: Un tube entêtant passe d’un coureur à l’autre | K7: 150 | L7: 2 | M7: 0.9 | N7: 88 | O7: 0 | P7: 0 | Q7: 0 | R7: 3 | S7: 0.85 | T7: 0.5 | U7: 1 | V7: #ff8fd0
A8: miner | B8: 矿机 | C8: Miner | D8: Mineur | E8: 矿机 | F8: Miner | G8: Mineur | H8: 不攻击，比赛中不停算题挖区块：挖到区块得聪和一次三选一 | I8: Doesn’t attack; keeps hashing during the race. Win a block for sats and a pick-one-of-three | J8: N’attaque pas ; calcule pendant la course. Bloc gagné : des sats et un choix parmi trois | K8: 120 | L8: 0 | M8: 1 | N8: 70 | O8: 0 | P8: 0 | Q8: 0 | R8: 0 | S8: 1 | T8: 1 | U8: 1 | V8: #f7931a
A9: gem | B9: 宝石发射器 | C9: Gem Launcher | D9: Lance-gemmes | E9: 宝石 | F9: Gems | G9: Gemmes | H9: 发射宝石：红宝石主攻暴击，黄宝石主攻连发和 GST，蓝宝石减速冻结 | I9: Fires gems: ruby for crits, topaz for multi-shot and GST, sapphire to slow and freeze | J9: Tire des gemmes : rubis pour les critiques, topaze pour les tirs multiples et le GST, saphir pour ralentir et geler | K9: 140 | L9: 1.5 | M9: 0.7 | N9: 100 | O9: 0 | P9: 0 | Q9: 0 | R9: 0 | S9: 1 | T9: 0.6 | U9: 1 | V9: #00a6f4

Sheet 升级路线
A1: 装置 id | B1: 路线 | C1: 路线名称（中文） | D1: 路线名称（English） | E1: 路线名称（Français）
A2: tower | B2: path | C2: name_zh | D2: name_en | E2: name_fr
A3: miner | B3: 1 | C3: 算力 | D3: Hash | E3: Puissance
A4: miner | B4: 2 | C4: 矿池 | D4: Pool | E4: Pool
A5: miner | B5: 3 | C5: 散热 | D5: Cooling | E5: Refroidissement
A6: gem | B6: 1 | C6: 红宝石 | D6: Ruby | E6: Rubis
A7: gem | B7: 2 | C7: 黄宝石 | D7: Topaz | E7: Topaze
A8: gem | B8: 3 | C8: 蓝宝石 | D8: Sapphire | E8: Saphir
A9: dart | B9: 1 | C9: 铁罐 | D9: Iron Can | E9: Canette en fer
A10: dart | B10: 2 | C10: 连投 | D10: Rapid Toss | E10: Lancers rapides
A11: dart | B11: 3 | C11: 瞄准 | D11: Aim | E11: Visée
A12: bomb | B12: 1 | C12: 大香蕉 | D12: Big Banana | E12: Grosse banane
A13: bomb | B13: 2 | C13: 一串香蕉 | D13: Banana Bunch | E13: Régime de bananes
A14: bomb | B14: 3 | C14: 辣椒油 | D14: Chili Oil | E14: Huile pimentée
... A23: tesla | B23: 3 | C23: 洗脑神曲 | D23: Earworm | E23: Tube entêtant

Sheet 升级
A1: 装置 id | B1: 路线 | C1: 等级 | D1: 名称（中文） | E1: 名称（English） | F1: 名称（Français） | G1: 价格 | H1: 说明（中文） | I1: 说明（English） | J1: 说明（Français） | K1: 效果（见「效果语法」） | L1: 本路线累计花费
A2: tower | B2: path | C2: tier | D2: name_zh | E2: name_en | F2: name_fr | G2: cost | H2: desc_zh | I2: desc_en | J2: desc_fr | K2: effect
A3: miner | B3: 1 | C3: 1 | D3: 超频 CPU | E3: Overclocked CPU | F3: CPU surcadencé | G3: 60 | H3: 算力 +50% | I3: Hash +50% | J3: Puissance +50 % | K3: hash*=1.5 | L3: =SUMIFS($G$3:$G$107,$A$3:$A$107,A3,$B$3:$B$107,B3,$C$3:$C$107,"<="&C3)
A4: miner | B4: 1 | C4: 2 | D4: 双核处理器 | E4: Dual-core CPU | F4: Processeur double cœur | G4: 120 | H4: 算力 +50% | I4: Hash +50% | J4: Puissance +50 % | K4: hash*=1.5 | L4: =SUMIFS($G$3:$G$107,$A$3:$A$107,A4,$B$3:$B$107,B4,$C$3:$C$107,"<="&C4)
A5: miner | B5: 1 | C5: 3 | D5: 显卡挖矿 | E5: GPU Mining | F5: Minage GPU | G5: 300 | H5: 算力 ×3（2010 年显卡挖矿开始流行） | I5: Hash ×3 (GPU mining took off in 2010) | J5: Puissance ×3 (le minage GPU décolle en 2010) | K5: hash*=3 | L5: =SUMIFS($G$3:$G$107,$A$3:$A$107,A5,$B$3:$B$107,B5,$C$3:$C$107,"<="&C5)
A6: miner | B6: 1 | C6: 4 | D6: 多卡矿机 | E6: Multi-GPU Rig | F6: Rig multi-GPU | G6: 700 | H6: 算力 ×2 | I6: Hash ×2 | J6: Puissance ×2 | K6: hash*=2 | L6: =SUMIFS($G$3:$G$107,$A$3:$A$107,A6,$B$3:$B$107,B6,$C$3:$C$107,"<="&C6)
A7: miner | B7: 1 | C7: 5 | D7: 显卡农场 | E7: GPU Farm | F7: Ferme GPU | G7: 1500 | H7: 算力 ×2.5 | I7: Hash ×2.5 | J7: Puissance ×2,5 | K7: hash*=2.5 | L7: =SUMIFS($G$3:$G$107,$A$3:$A$107,A7,$B$3:$B$107,B7,$C$3:$C$107,"<="&C7)
A8: miner | B8: 2 | C8: 1 | D8: 加入矿池 | E8: Join a Pool | F8: Rejoindre un pool | G8: 70 | H8: 出块奖励 +25% | I8: Block reward +25% | J8: Récompense de bloc +25 % | K8: blockBonus+=0.25 | L8: =SUMIFS($G$3:$G$107,$A$3:$A$107,A8,$B$3:$B$107,B8,$C$3:$C$107,"<="&C8)
A9: miner | B9: 2 | C9: 2 | D9: 矿池分成 | E9: Pool Payout | F9: Partage du pool | G9: 140 | H9: 射程内其他装置效果 +15% | I9: Other devices in range: effect +15% | J9: Autres dispositifs à portée : effet +15 % | K9: auraDmg=1.15 | L9: =SUMIFS($G$3:$G$107,$A$3:$A$107,A9,$B$3:$B$107,B9,$C$3:$C$107,"<="&C9)
A10: miner | B10: 2 | C10: 3 | D10: 稳定收益 | E10: Steady Income | F10: Revenu stable | G10: 320 | H10: 出块奖励再 +50% | I10: Block reward +50% more | J10: Récompense de bloc encore +50 % | K10: blockBonus+=0.5 | L10: =SUMIFS($G$3:$G$107,$A$3:$A$107,A10,$B$3:$B$107,B10,$C$3:$C$107,"<="&C10)
A11: miner | B11: 2 | C11: 4 | D11: 大矿池 | E11: Big Pool | F11: Gros pool | G11: 700 | H11: 射程内其他装置效果 +30%，射程 +30 | I11: Other devices in range: effect +30%; range +30 | J11: Autres dispositifs à portée : effet +30 % ; portée +30 | K11: auraDmg=1.3; range+=30 | L11: =SUMIFS($G$3:$G$107,$A$3:$A$107,A11,$B$3:$B$107,B11,$C$3:$C$107,"<="&C11)
A12: miner | B12: 2 | C12: 5 | D12: 算力联盟 | E12: Hash Alliance | F12: Alliance de puissance | G12: 1500 | H12: 出块奖励再 +100%，射程内装置出手间隔 −15% | I12: Block reward +100% more; devices in range: interval −15% | J12: Récompense encore +100 % ; dispositifs à portée : intervalle −15 % | K12: blockBonus+=1; auraRate=0.85 | L12: =SUMIFS($G$3:$G$107,$A$3:$A$107,A12,$B$3:$B$107,B12,$C$3:$C$107,"<="&C12)
A13: miner | B13: 3 | C13: 1 | D13: 风扇狂转 | E13: Fans Roaring | F13: Ventilos à fond | G13: 60 | H13: 吹出热风：射程内跑者每秒受 1 点效果并挂上“热” | I13: Blows hot air: runners in range take 1 effect per second and get “Heat” | J13: Souffle de l’air chaud : coureurs à portée subissent 1 effet par seconde et reçoivent « Chaleur » | K13: heat+=1 | L13: =SUMIFS($G$3:$G$107,$A$3:$A$107,A13,$B$3:$B$107,B13,$C$3:$C$107,"<="&C13)
A14: miner | B14: 3 | C14: 2 | D14: 机箱漏风 | E14: Leaky Case | F14: Boîtier qui fuit | G14: 120 | H14: 热风 +2 | I14: Heat +2 | J14: Chaleur +2 | K14: heat+=2 | L14: =SUMIFS($G$3:$G$107,$A$3:$A$107,A14,$B$3:$B$107,B14,$C$3:$C$107,"<="&C14)
... A107: tesla | B107: 3 | C107: 5 | D107: 广场舞女王 | E107: Dance Floor Queen | F107: Reine de la piste | G107: 1600 | H107: 出手间隔 −30%，多传 3 人 | I107: Interval −30%, chains 3 more | J107: Intervalle −30 %, 3 de plus en chaîne | K107: rate*=0.7; chain+=3 | L107: =SUMIFS($G$3:$G$107,$A$3:$A$107,A107,$B$3:$B$107,B107,$C$3:$C$107,"<="&C107)

Sheet 敌人
A1: id | B1: 名称（中文） | C1: 名称（English） | D1: 名称（Français） | E1: 体型半径 | F1: 移速 | G1: 劝退 GST | H1: 计分权重 | I1: 漏过扣能量
A2: id | B2: name_zh | C2: name_en | D2: name_fr | E2: radius | F2: speed | G2: gold | H2: value | I2: leak
A3: norm | B3: 慢跑者 | C3: Jogger | D3: Joggeur | E3: 9 | F3: 55 | G3: 6 | H3: 1 | I3: 1
A4: arm | B4: 耐力跑者 | C4: Endurance runner | D4: Coureur endurant | E4: 11 | F4: 42 | G4: 12 | H4: 2 | I4: 2
A5: boss | B5: 传奇跑者 | C5: Legendary runner | D5: Coureur légendaire | E5: 22 | F5: 26 | G5: 80 | H5: 15 | I5: 10
A6: rain | B6: 雨衣跑者 | C6: Raincoat Runner | D6: Coureur en ciré | E6: 9 | F6: 52 | G6: 8 | H6: 1 | I6: 1
A7: hop | B7: 弹簧鞋跑者 | C7: Spring-Shoe Runner | D7: Coureur à ressorts | E7: 9 | F7: 62 | G7: 8 | H7: 1 | I7: 1
A8: phones | B8: 降噪耳机跑者 | C8: Headphones Runner | D8: Coureur au casque | E8: 9 | F8: 55 | G8: 8 | H8: 1 | I8: 1
A9: whale | B9: 巨鲸 | C9: Whale | D9: Baleine | E9: 15 | F9: 30 | G9: 30 | H9: 4 | I9: 3
A11: ※ 体力按波次配置，见「波次」表。雨衣/弹簧鞋/降噪耳机跑者体力 = 慢跑者体力 × hpRain/hpHop/hpPhones，巨鲸 = 耐力跑者体力 × hpWhale（见「全局」）。克制：雨衣跑者不怕洒水器；弹簧鞋跑者跳过香蕉皮（懵时除外）；降噪耳机跑者不怕音响；巨鲸削弱单次效果低于 whaleMin 的攻击。

Sheet 波次
A1: 波次 | B1: 慢跑者人数 | C1: 耐力跑者人数 | D1: 慢跑者体力 | E1: 耐力跑者体力 | F1: 是否 Boss 波（1/0） | G1: Boss 体力 | H1: 词缀数量 | I1: 雨衣跑者 | J1: 弹簧鞋跑者 | K1: 降噪耳机跑者 | L1: 巨鲸 | M1: 本波总人数
A2: wave | B2: normals | C2: armored | D2: normHp | E2: armHp | F2: boss | G2: bossHp | H2: affixes | I2: rain | J2: hop | K2: phones | L2: whale
A3: 1 | B3: 30 | C3: 0 | D3: 3.2 | E3: 7.7 | F3: 0 | G3: 0 | H3: 0 | I3: 0 | J3: 0 | K3: 0 | L3: 0 | M3: =B3+C3+F3+SUM(I3:L3)
A4: 2 | B4: 36 | C4: 0 | D4: 4.4 | E4: 10.3 | F4: 0 | G4: 0 | H4: 0 | I4: 0 | J4: 0 | K4: 0 | L4: 0 | M4: =B4+C4+F4+SUM(I4:L4)
A5: 3 | B5: 39 | C5: 6 | D5: 5.8 | E5: 13.3 | F5: 0 | G5: 0 | H5: 0 | I5: 0 | J5: 0 | K5: 0 | L5: 0 | M5: =B5+C5+F5+SUM(I5:L5)
A6: 4 | B6: 45 | C6: 9 | D6: 7.4 | E6: 16.7 | F6: 0 | G6: 0 | H6: 1 | I6: 4 | J6: 0 | K6: 0 | L6: 0 | M6: =B6+C6+F6+SUM(I6:L6)
A7: 5 | B7: 51 | C7: 12 | D7: 9.2 | E7: 20.5 | F7: 1 | G7: 100 | H7: 1 | I7: 5 | J7: 0 | K7: 0 | L7: 0 | M7: =B7+C7+F7+SUM(I7:L7)
A8: 6 | B8: 57 | C8: 15 | D8: 11.2 | E8: 24.7 | F8: 0 | G8: 0 | H8: 1 | I8: 6 | J8: 5 | K8: 0 | L8: 0 | M8: =B8+C8+F8+SUM(I8:L8)
A9: 7 | B9: 60 | C9: 18 | D9: 13.4 | E9: 29.3 | F9: 0 | G9: 0 | H9: 1 | I9: 6 | J9: 5 | K9: 0 | L9: 0 | M9: =B9+C9+F9+SUM(I9:L9)
A10: 8 | B10: 66 | C10: 21 | D10: 15.8 | E10: 34.3 | F10: 0 | G10: 0 | H10: 1 | I10: 7 | J10: 5 | K10: 5 | L10: 0 | M10: =B10+C10+F10+SUM(I10:L10)
A11: 9 | B11: 72 | C11: 24 | D11: 19.5 | E11: 42.08 | F11: 0 | G11: 0 | H11: 1 | I11: 7 | J11: 6 | K11: 6 | L11: 0 | M11: =B11+C11+F11+SUM(I11:L11)
A12: 10 | B12: 78 | C12: 27 | D12: 23.74 | E12: 50.96 | F12: 1 | G12: 420 | H12: 2 | I12: 8 | J12: 6 | K12: 6 | L12: 1 | M12: =B12+C12+F12+SUM(I12:L12)
A13: 11 | B13: 81 | C13: 33 | D13: 28.56 | E13: 61.01 | F13: 0 | G13: 0 | H13: 1 | I13: 8 | J13: 6 | K13: 6 | L13: 1 | M13: =B13+C13+F13+SUM(I13:L13)
A14: 12 | B14: 87 | C14: 36 | D14: 33.98 | E14: 72.29 | F14: 0 | G14: 0 | H14: 1 | I14: 9 | J14: 7 | K14: 7 | L14: 2 | M14: =B14+C14+F14+SUM(I14:L14)
... A17: 15 | B17: 102 | C17: 45 | D17: 54.24 | E17: 114.31 | F17: 1 | G17: 1400 | H17: 2 | I17: 10 | J17: 8 | K17: 8 | L17: 3 | M17: =B17+C17+F17+SUM(I17:L17)
A19: ※ 行数就是总波数，可以增删行；精英小队的词缀数量见「全局」eliteAffixes。

Sheet Boss
A1: id | B1: 启用（1/0） | C1: 名字 | D1: 称号（中文） | E1: 称号（English） | F1: 称号（Français） | G1: 能力说明（中文） | H1: 能力说明（English） | I1: 能力说明（Français） | J1: p1 | K1: p2 | L1: p3 | M1: p4 | N1: p1–p4 含义
A2: id | B2: enabled | C2: name | D2: title_zh | E2: title_en | F2: title_fr | G2: ability_zh | H2: ability_en | I2: ability_fr | J2: p1 | K2: p2 | L2: p3 | M2: p4
A3: yawn | B3: 1 | C3: Nox | D3: 黑猫 | E3: Black Cat | F3: Chat noir | G3: 九命：第一次退赛会原地复活（40% 体力） | H3: Nine Lives: revives once on the spot (40% stamina) | I3: Neuf vies : revient une fois sur place (40 % d’endurance) | J3: 0.4 | K3: 1 | L3: 0 | M3: 0 | N3: p1 = 复活体力比例；p2 = 复活后无敌秒数
A4: gilg | B4: 1 | C4: Aurum | D4: 金王 | E4: Golden King | F4: Roi doré | G4: 王之宝库：每 4 秒召唤 2 名金甲跑者 | H4: Royal Treasury: summons 2 golden runners every 4 s | I4: Trésor royal : invoque 2 coureurs dorés toutes les 4 s | J4: 4 | K4: 2 | L4: 8 | M4: 0.8 | N4: p1 = 召唤间隔（秒）；p2 = 每次召唤人数；p3 = 最多召唤人数；p4 = 金甲跑者体力倍率
A5: king | B5: 1 | C5: Slimo | D5: 黏液国王 | E5: Slime King | F5: Roi visqueux | G5: 黏液王冠：身后留下黏液，踩到的跑者加速 30% 并回体力 | H5: Slime Crown: leaves a slime trail; runners on it get +30% speed and recover stamina | I5: Couronne visqueuse : laisse une traînée ; les coureurs dessus gagnent +30 % de vitesse et récupèrent | J5: 0.3 | K5: 1.3 | L5: 0.04 | M5: 5 | N5: p1 = 黏液间隔（秒）；p2 = 黏液上速度倍率；p3 = 黏液上每秒回复比例；p4 = 黏液持续（秒）
A6: lucas | B6: 1 | C6: Rocco | D6: 光头 | E6: Bald Dasher | F6: Crâne rasé | G6: 铁头冲刺：每 5 秒冲刺 1 秒，3 倍速 | H6: Headstrong Dash: every 5 s, sprints at ×3 speed for 1 s | I6: Charge tête baissée : toutes les 5 s, sprint ×3 pendant 1 s | J6: 5 | K6: 1 | L6: 3 | M6: 0 | N6: p1 = 冲刺间隔（秒）；p2 = 冲刺时长（秒）；p3 = 冲刺速度倍率
A7: shiti | B7: 1 | C7: Chuckles | D7: 笑声 | E7: Laughter | F7: Fou rire | G7: 开怀大笑：每 6 秒大笑一次，身边的装置停工 1.5 秒 | H7: Big Laugh: every 6 s, nearby devices stop for 1.5 s | I7: Fou rire : toutes les 6 s, les dispositifs proches s’arrêtent 1,5 s | J7: 6 | K7: 130 | L7: 1.5 | M7: 0 | N7: p1 = 大笑间隔（秒）；p2 = 影响半径；p3 = 装置停工（秒）
A8: pizza | B8: 1 | C8: Pizza Rider | D8: 披萨外卖员 | E8: Pizza courier | F8: Livreur de pizza | G8: 一万枚换两个披萨：体力掉到 2/3 和 1/3 时各扔下一盒披萨，冒出一群披萨跑者 | H8: 10,000 coins for two pizzas: at 2/3 and 1/3 stamina he drops a pizza box and a swarm of pizza runners pours out | I8: 10 000 pièces pour deux pizzas : à 2/3 et 1/3 d’endurance, il lâche une boîte et une nuée de coureurs-pizza en sort | J8: 5 | K8: 0.22 | L8: 0 | M8: 0 | N8: p1 = 每盒披萨冒出几个跑者；p2 = 披萨跑者体力占比
A9: overflow | B9: 1 | C9: Overflow | D9: 溢出怪 | E9: The Overflow | F9: Le Débordement | G9: 整数溢出：第一次倒下时分裂成两个，各带 60% 体力；几秒后“软分叉”修复，两个都掉一半体力 | H9: Integer overflow: the first time it falls it splits into two, each with 60% stamina; a few seconds later a “soft fork” patch halves both | I9: Dépassement d’entier : la première fois qu’il tombe, il se divise en deux, chacun à 60 % d’endurance ; quelques secondes plus tard, un « soft fork » coupe leur endurance de moitié | J9: 4 | K9: 0.5 | L9: 0 | M9: 0 | N9: p1 = 软分叉延迟（秒）；p2 = 软分叉扣除体力比例
A10: jerry | B10: 1 | C10: Datto | D10: 数据控 | E10: Data Nerd | F10: Fan de données | G10: 数据分析：每 3 秒对受到最多的装置类型产生 65% 抗性 | H10: Data Analysis: every 3 s gains 65% resistance to the device hitting him most | I10: Analyse de données : toutes les 3 s, résiste à 65 % au dispositif qui le touche le plus | J10: 3 | K10: 0.65 | L10: 0 | M10: 0 | N10: p1 = 统计间隔（秒）；p2 = 抗性比例

Sheet 词缀
A1: id | B1: 名称（中文） | C1: 名称（English） | D1: 名称（Français） | E1: 说明（中文） | F1: 说明（English） | G1: 说明（Français）
A2: id | B2: name_zh | C2: name_en | D2: name_fr | E2: desc_zh | F2: desc_en | G2: desc_fr
A3: swift | B3: 冲刺 | C3: Sprint | D3: Sprint | E3: 移速 +40% | F3: Speed +40% | G3: Vitesse +40 %
A4: regen | B4: 补给 | C4: Refuel | D4: Ravitaillement | E4: 1 秒没被干扰就回体力 | F4: Recovers stamina after 1 s undisturbed | G4: Récupère de l’endurance après 1 s sans gêne
A5: shield | B5: 能量盾 | C5: Energy Shield | D5: Bouclier d’énergie | E5: 额外 35% 能量护盾 | F5: Extra 35% energy shield | G5: Bouclier d’énergie +35 %
A6: split | B6: 跑团 | C6: Running Club | D6: Club de course | E6: 退赛时 2 名跟跑者接力 | F6: 2 pacers take over when one quits | G6: 2 meneurs prennent le relais à l’abandon
A8: ※ 词缀数值（冲刺倍率、补给回复、能量盾比例、跟跑者体力）在「全局」表。

Sheet 卡牌
A1: id | B1: 启用（1/0） | C1: 类别 | D1: 稀有度（C/R/L） | E1: 可重复（1/0） | F1: 名称（中文） | G1: 名称（English） | H1: 名称（Français） | I1: 说明（中文） | J1: 说明（English） | K1: 说明（Français） | L1: 数值 v1 | M1: 数值 v2 | N1: v1 / v2 含义
A2: id | B2: enabled | C2: tag | D2: rar | E2: stack | F2: name_zh | G2: name_en | H2: name_fr | I2: desc_zh | J2: desc_en | K2: desc_fr | L2: v1 | M2: v2
A3: u_bomb | B3: 1 | C3: 装置 | D3: C | E3: 0 | F3: 香蕉皮投手 | G3: Banana Peeler | H3: Lanceur de peaux de banane | I3: 解锁香蕉皮投手：一片跑者一起滑倒，专克耐力跑者 | J3: Unlock Banana Peeler: trips whole groups, counters endurance runners | K3: Débloque le Lanceur de peaux : fait glisser des groupes, contre les endurants | L3: 0 | M3: 0
A4: u_frost | B4: 1 | C4: 装置 | D4: C | E4: 0 | F4: 洒水器 | G4: Sprinkler | H4: Arroseur | I4: 解锁洒水器：跑道湿滑，范围减速 | J4: Unlock Sprinkler: wet track, area slow | K4: Débloque l’Arroseur : piste glissante, ralentit une zone | L4: 0 | M4: 0
A5: u_sniper | B5: 1 | C5: 装置 | D5: R | E5: 0 | F5: 鞋盒无人机 | G5: Shoebox Drone | H5: Drone à boîtes | I5: 解锁鞋盒无人机：全图空投鞋盒，无视耐力 | J5: Unlock Shoebox Drone: map-wide drops, ignores endurance | K5: Débloque le Drone à boîtes : largages partout, ignore l’endurance | L5: 0 | M5: 0
A6: u_tesla | B6: 1 | C6: 装置 | D6: R | E6: 0 | F6: 广场舞音响 | G6: Dance Speaker | H6: Enceinte de danse | I6: 解锁广场舞音响：洗脑神曲在跑者之间传播 | J6: Unlock Dance Speaker: an earworm hops between runners | K6: Débloque l’Enceinte de danse : un tube passe de coureur en coureur | L6: 0 | M6: 0
A7: u_miner | B7: 1 | C7: 装置 | D7: R | E7: 0 | F7: 矿机 | G7: Miner | H7: Mineur | I7: 解锁矿机：挖区块得聪，并触发区块奖励三选一 | J7: Unlock the Miner: mine blocks for sats and a block-reward pick | K7: Débloque le Mineur : mine des blocs pour des sats et un choix de récompense | L7: 0 | M7: 0
A8: u_gem | B8: 1 | C8: 装置 | D8: R | E8: 0 | F8: 宝石发射器 | G8: Gem Launcher | H8: Lance-gemmes | I8: 解锁宝石发射器：红、黄、蓝三种宝石对应三条路线 | J8: Unlock the Gem Launcher: ruby, topaz and sapphire are its three paths | K8: Débloque le Lance-gemmes : rubis, topaze et saphir sont ses trois voies | L8: 0 | M8: 0
A9: pad | B9: 1 | C9: 道具 | D9: R | E9: 1 | F9: 额外放置点 | G9: Extra Spot | H9: Emplacement bonus | I9: 获得 1 个放置点：点地图上跑道以外的空地，新增一个装置空位 | J9: Gain 1 spot: tap open ground off the track to add a new device spot | K9: Gagne 1 emplacement : touche un terrain libre hors de la piste pour créer un emplacement | L9: 1 | M9: 0 | N9: v1 = 放置点个数
A10: freeup | B10: 1 | C10: 道具 | D10: C | E10: 1 | F10: 鞋匠 | G10: Cobbler | H10: Cordonnier | I10: 场上一个装置沿主路线免费升 1 级（没有装置时改为 +100 GST） | J10: One device gets a free tier on its main path (+100 GST if you have none) | K10: Un dispositif gagne un niveau gratuit sur sa voie principale (+100 GST si aucun) | L10: 0 | M10: 0
A11: coupon | B11: 1 | C11: 道具 | D11: C | E11: 1 | F11: 升级卷轴 | G11: Level-up Scroll | H11: Parchemin d’amélioration | I11: 接下来 3 次路线升级半价 | J11: Next 3 path upgrades are half price | K11: Les 3 prochaines améliorations à moitié prix | L11: 3 | M11: 0 | N11: v1 = 半价次数
A12: m_dart | B12: 1 | C12: 徽章 | D12: R | E12: 0 | F12: （自动） | G12: （自动） | H12: （自动） | I12: （自动） | J12: （自动） | K12: （自动） | L12: 0 | M12: 0 | N12: 名称和说明自动生成
A13: m_bomb | B13: 1 | C13: 徽章 | D13: R | E13: 0 | F13: （自动） | G13: （自动） | H13: （自动） | I13: （自动） | J13: （自动） | K13: （自动） | L13: 0 | M13: 0 | N13: 名称和说明自动生成
A14: m_frost | B14: 1 | C14: 徽章 | D14: R | E14: 0 | F14: （自动） | G14: （自动） | H14: （自动） | I14: （自动） | J14: （自动） | K14: （自动） | L14: 0 | M14: 0 | N14: 名称和说明自动生成
A15: m_sniper | B15: 1 | C15: 徽章 | D15: R | E15: 0 | F15: （自动） | G15: （自动） | H15: （自动） | I15: （自动） | J15: （自动） | K15: （自动） | L15: 0 | M15: 0 | N15: 名称和说明自动生成
A16: m_tesla | B16: 1 | C16: 徽章 | D16: R | E16: 0 | F16: （自动） | G16: （自动） | H16: （自动） | I16: （自动） | J16: （自动） | K16: （自动） | L16: 0 | M16: 0 | N16: 名称和说明自动生成
A17: m_miner | B17: 1 | C17: 徽章 | D17: R | E17: 0 | F17: （自动） | G17: （自动） | H17: （自动） | I17: （自动） | J17: （自动） | K17: （自动） | L17: 0 | M17: 0 | N17: 名称和说明自动生成
A18: m_gem | B18: 1 | C18: 徽章 | D18: R | E18: 0 | F18: （自动） | G18: （自动） | H18: （自动） | I18: （自动） | J18: （自动） | K18: （自动） | L18: 0 | M18: 0 | N18: 名称和说明自动生成
A19: breaker | B19: 1 | C19: 道具 | D19: L | E19: 0 | F19: 创世鞋 | G19: Genesis Sneaker | H19: Sneaker Genesis | I19: 所有装置的次路线上限 2 级 → 3 级 | J19: Secondary path cap 2 → 3 for all devices | K19: Plafond de la voie secondaire 2 → 3 pour tous | L19: 0 | M19: 0 | N19: 上限见全局 secCapBreaker
A20: drill | B20: 1 | C20: 宝石 | D20: C | E20: 1 | F20: 效率宝石 | G20: Efficiency Gem | H20: Gemme d’efficacité | I20: 所有装置效果 +15%（可叠加） | J20: All devices +15% effect (stacks) | K20: Tous les dispositifs +15 % d’effet (cumulable) | L20: 0.15 | M20: 0 | N20: v1 = 效果加成
A21: crit | B21: 1 | C21: 宝石 | D21: C | E21: 1 | F21: 幸运宝石 | G21: Luck Gem | H21: Gemme de chance | I21: 暴击率 +10%（可叠加） | J21: Crit chance +10% (stacks) | K21: Chance de critique +10 % (cumulable) | L21: 0.1 | M21: 0 | N21: v1 = 暴击率加成
A22: heart | B22: 1 | C22: 宝石 | D22: C | E22: 1 | F22: 舒适宝石 | G22: Comfort Gem | H22: Gemme de confort | I22: 生命 +6 | J22: Lives +6 | K22: Vies +6 | L22: 6 | M22: 0 | N22: v1 = 生命
... A34: overclock | B34: 1 | C34: 道具 | D34: L | E34: 0 | F34: 马拉松模式 | G34: Marathon Mode | H34: Mode marathon | I34: 燃脂模式持续 10 秒，出手速度 ×2 | J34: Fat-burn mode lasts 10 s at ×2 speed | K34: Le mode brûle-graisse dure 10 s à vitesse ×2 | L34: 0 | M34: 0 | N34: 数值见全局
A36: ※ 徽章卡（m_ 开头）的名称和说明由装置简称自动生成，填写无效。稀有度权重在「全局」rarityC/R/L。

Sheet 跑道列表
A1: id | B1: 启用（1/0） | C1: 名称（中文） | D1: 名称（English） | E1: 名称（Français） | F1: 说明（中文） | G1: 说明（English） | H1: 说明（Français） | I1: 对手移速倍率 | J1: 对手体力倍率 | K1: 入口 / 出口 / 路线数
A2: id | B2: enabled | C2: name_zh | D2: name_en | E2: name_fr | F2: desc_zh | G2: desc_en | H2: desc_fr | I2: spdMult | J2: hpMult
A3: classic | B3: 1 | C3: 蛇形跑道 | D3: Serpentine | E3: Serpentin | F3: 1 进 1 出：一条长蛇形跑道，经典布局 | G3: 1 in, 1 out: one long winding track, the classic layout. | H3: 1 entrée, 1 sortie : une longue piste sinueuse, le tracé classique. | I3: 1 | J3: 1 | K3: 1 进 1 出 · 1 条路线
A4: twin | B4: 1 | C4: 双子跑道 | D4: Twin Tracks | E4: Pistes jumelles | F4: 2 进 2 出：两条互不相交的跑道，中间一列空位可以同时照顾两边 | G4: 2 in, 2 out: two separate tracks; the middle column of spots can cover both. | H4: 2 entrées, 2 sorties : deux pistes séparées ; la colonne centrale couvre les deux. | I4: 0.85 | J4: 1 | K4: 2 进 2 出 · 2 条路线
A5: fork | B5: 1 | C5: 分岔路口 | D5: The Fork | E5: La Fourche | F5: 1 进 2 出：跑者在路口分成左右两路，入口处是必争之地 | G5: 1 in, 2 out: runners split left and right at the junction, so the entrance is key. | H5: 1 entrée, 2 sorties : les coureurs se séparent au carrefour ; l’entrée est décisive. | I5: 0.85 | J5: 1 | K5: 1 进 2 出 · 2 条路线
A6: merge | B6: 1 | C6: 汇流跑道 | D6: Confluence | E6: Confluence | F6: 2 进 1 出：两路跑者从两侧进场，在中间汇合后一起冲向终点 | G6: 2 in, 1 out: runners enter from both sides, merge in the middle and rush the finish together. | H6: 2 entrées, 1 sortie : les coureurs arrivent des deux côtés, se rejoignent au centre et filent ensemble. | I6: 0.95 | J6: 1 | K6: 2 进 1 出 · 2 条路线
A7: cross | B7: 1 | C7: 十字路口 | D7: Crossroads | E7: Carrefour | F7: 2 进 2 出：一路从上到下、一路从左到右，两条跑道在右下交叉 | G7: 2 in, 2 out: one track runs top to bottom, the other left to right; they cross at the bottom right. | H7: 2 entrées, 2 sorties : une piste du haut vers le bas, l’autre de gauche à droite ; elles se croisent en bas à droite. | I7: 0.8 | J7: 1 | K7: 2 进 2 出 · 2 条路线
A8: trident | B8: 1 | C8: 三路汇聚 | D8: Trident | E8: Trident | F8: 3 进 1 出：左右两路绕远，中路直冲终点，要优先守住中路 | G8: 3 in, 1 out: the side tracks loop around while the middle one runs straight to the finish, so guard the middle first. | H8: 3 entrées, 1 sortie : les côtés font un détour, le centre file droit à l’arrivée ; protège le centre en priorité. | I8: 0.8 | J8: 1 | K8: 3 进 1 出 · 3 条路线
A10: ※ 每局开始时从启用的跑道里随机选一条（游戏里也可以手动指定）。新增跑道：在这里加一行 id，再到「地图」表填坐标。

Sheet 地图
A1: 跑道 id | B1: 类型（path=路线点，pad=空位） | C1: 路线编号 | D1: 顺序 | E1: x | F1: y
A2: map | B2: type | C2: route | D2: order | E2: x | F2: y
A3: classic | B3: path | C3: 1 | D3: 1 | E3: -24 | F3: 80
A4: classic | B4: path | C4: 1 | D4: 2 | E4: 300 | F4: 80
A5: classic | B5: path | C5: 1 | D5: 3 | E5: 300 | F5: 220
A6: classic | B6: path | C6: 1 | D6: 4 | E6: 60 | F6: 220
A7: classic | B7: path | C7: 1 | D7: 5 | E7: 60 | F7: 360
A8: classic | B8: path | C8: 1 | D8: 6 | E8: 300 | F8: 360
A9: classic | B9: path | C9: 1 | D9: 7 | E9: 300 | F9: 500
A10: classic | B10: path | C10: 1 | D10: 8 | E10: 180 | F10: 500
A11: classic | B11: path | C11: 1 | D11: 9 | E11: 180 | F11: 640
A12: classic | B12: pad | D12: 1 | E12: 40 | F12: 150
A13: classic | B13: pad | D13: 2 | E13: 120 | F13: 150
A14: classic | B14: pad | D14: 3 | E14: 200 | F14: 150
A15: classic | B15: pad | D15: 4 | E15: 250 | F15: 150
A16: classic | B16: pad | D16: 5 | E16: 120 | F16: 290
A17: classic | B17: pad | D17: 6 | E17: 200 | F17: 290
A18: classic | B18: pad | D18: 7 | E18: 260 | F18: 290
A19: classic | B19: pad | D19: 8 | E19: 335 | F19: 290
A20: classic | B20: pad | D20: 9 | E20: 30 | F20: 430
A21: classic | B21: pad | D21: 10 | E21: 110 | F21: 430
A22: classic | B22: pad | D22: 11 | E22: 190 | F22: 430
A23: classic | B23: pad | D23: 12 | E23: 250 | F23: 430
... A25: classic | B25: pad | D25: 14 | E25: 260 | F25: 560
A26: twin | B26: path | C26: 1 | D26: 1 | E26: 60 | F26: -24
A27: twin | B27: path | C27: 1 | D27: 2 | E27: 60 | F27: 180
A28: twin | B28: path | C28: 1 | D28: 3 | E28: 140 | F28: 180
A29: twin | B29: path | C29: 1 | D29: 4 | E29: 140 | F29: 420
A30: twin | B30: path | C30: 1 | D30: 5 | E30: 60 | F30: 420
A31: twin | B31: path | C31: 1 | D31: 6 | E31: 60 | F31: 624
A32: twin | B32: path | C32: 2 | D32: 1 | E32: 300 | F32: -24
A33: twin | B33: path | C33: 2 | D33: 2 | E33: 300 | F33: 180
A34: twin | B34: path | C34: 2 | D34: 3 | E34: 220 | F34: 180
A35: twin | B35: path | C35: 2 | D35: 4 | E35: 220 | F35: 420
A36: twin | B36: path | C36: 2 | D36: 5 | E36: 300 | F36: 420
A37: twin | B37: path | C37: 2 | D37: 6 | E37: 300 | F37: 624
A38: twin | B38: pad | D38: 1 | E38: 180 | F38: 100
A39: twin | B39: pad | D39: 2 | E39: 100 | F39: 100
A40: twin | B40: pad | D40: 3 | E40: 260 | F40: 100
A41: twin | B41: pad | D41: 4 | E41: 180 | F41: 230
...

Sheet 美术资源
A1: 资源编号（勿改） | B1: 类别 | C1: 说明 | D1: 优先级 | E1: 图片地址（https:// 链接，留空 = 用占位图） | F1: 游戏内宽 | G1: 游戏内高 | H1: 锚点 X（0–1） | I1: 锚点 Y（0–1） | J1: 帧数 | K1: 帧率 | L1: 盖住跑道（1/0，仅地图） | M1: 建议出图尺寸（3 倍，px）
A2: key | E2: src | F2: w | G2: h | H2: ax | I2: ay | J2: frames | K2: fps | L2: cover
A3: map.classic | B3: 地图 | C3: 蛇形跑道整张底图（草地、装饰；cover=1 时连跑道一起画，游戏就不再画跑道） | D3: P1 样板关 | F3: 360 | G3: 600 | H3: 0 | I3: 0 | J3: 1 | K3: 0 | L3: 0 | M3: =IF(J3>1,J3*F3*3&" × "&G3*3&"（"&J3&" 帧横排）",F3*3&" × "&G3*3)
A4: map.twin | B4: 地图 | C4: 双子跑道整张底图（草地、装饰；cover=1 时连跑道一起画，游戏就不再画跑道） | D4: P2 | F4: 360 | G4: 600 | H4: 0 | I4: 0 | J4: 1 | K4: 0 | L4: 0 | M4: =IF(J4>1,J4*F4*3&" × "&G4*3&"（"&J4&" 帧横排）",F4*3&" × "&G4*3)
A5: map.fork | B5: 地图 | C5: 分岔路口整张底图（草地、装饰；cover=1 时连跑道一起画，游戏就不再画跑道） | D5: P2 | F5: 360 | G5: 600 | H5: 0 | I5: 0 | J5: 1 | K5: 0 | L5: 0 | M5: =IF(J5>1,J5*F5*3&" × "&G5*3&"（"&J5&" 帧横排）",F5*3&" × "&G5*3)
A6: map.merge | B6: 地图 | C6: 汇流跑道整张底图（草地、装饰；cover=1 时连跑道一起画，游戏就不再画跑道） | D6: P2 | F6: 360 | G6: 600 | H6: 0 | I6: 0 | J6: 1 | K6: 0 | L6: 0 | M6: =IF(J6>1,J6*F6*3&" × "&G6*3&"（"&J6&" 帧横排）",F6*3&" × "&G6*3)
A7: map.cross | B7: 地图 | C7: 十字路口整张底图（草地、装饰；cover=1 时连跑道一起画，游戏就不再画跑道） | D7: P2 | F7: 360 | G7: 600 | H7: 0 | I7: 0 | J7: 1 | K7: 0 | L7: 0 | M7: =IF(J7>1,J7*F7*3&" × "&G7*3&"（"&J7&" 帧横排）",F7*3&" × "&G7*3)
A8: map.trident | B8: 地图 | C8: 三路汇聚整张底图（草地、装饰；cover=1 时连跑道一起画，游戏就不再画跑道） | D8: P2 | F8: 360 | G8: 600 | H8: 0 | I8: 0 | J8: 1 | K8: 0 | L8: 0 | M8: =IF(J8>1,J8*F8*3&" × "&G8*3&"（"&J8&" 帧横排）",F8*3&" × "&G8*3)
A9: tower.dart | B9: 装置 | C9: 易拉罐投手：操作员 + 道具，面朝右（朝左时游戏自动翻转），脚底对齐空位中心 | D9: P1 样板关 | F9: 40 | G9: 50 | H9: 0.5 | I9: 0.92 | J9: 1 | K9: 0 | L9: 0 | M9: =IF(J9>1,J9*F9*3&" × "&G9*3&"（"&J9&" 帧横排）",F9*3&" × "&G9*3)
A10: tower.bomb | B10: 装置 | C10: 香蕉皮投手：操作员 + 道具，面朝右（朝左时游戏自动翻转），脚底对齐空位中心 | D10: P1 样板关 | F10: 40 | G10: 50 | H10: 0.5 | I10: 0.92 | J10: 1 | K10: 0 | L10: 0 | M10: =IF(J10>1,J10*F10*3&" × "&G10*3&"（"&J10&" 帧横排）",F10*3&" × "&G10*3)
A11: tower.frost | B11: 装置 | C11: 洒水器：操作员 + 道具，面朝右（朝左时游戏自动翻转），脚底对齐空位中心 | D11: P2 | F11: 40 | G11: 50 | H11: 0.5 | I11: 0.92 | J11: 1 | K11: 0 | L11: 0 | M11: =IF(J11>1,J11*F11*3&" × "&G11*3&"（"&J11&" 帧横排）",F11*3&" × "&G11*3)
A12: tower.sniper | B12: 装置 | C12: 鞋盒无人机：操作员 + 道具，面朝右（朝左时游戏自动翻转），脚底对齐空位中心 | D12: P2 | F12: 40 | G12: 50 | H12: 0.5 | I12: 0.92 | J12: 1 | K12: 0 | L12: 0 | M12: =IF(J12>1,J12*F12*3&" × "&G12*3&"（"&J12&" 帧横排）",F12*3&" × "&G12*3)
A13: tower.tesla | B13: 装置 | C13: 广场舞音响：操作员 + 道具，面朝右（朝左时游戏自动翻转），脚底对齐空位中心 | D13: P2 | F13: 40 | G13: 50 | H13: 0.5 | I13: 0.92 | J13: 1 | K13: 0 | L13: 0 | M13: =IF(J13>1,J13*F13*3&" × "&G13*3&"（"&J13&" 帧横排）",F13*3&" × "&G13*3)
A14: tower.gem | B14: 装置 | C14: 宝石发射器：操作员 + 道具，面朝右（朝左时游戏自动翻转），脚底对齐空位中心 | D14: P2 | F14: 40 | G14: 50 | H14: 0.5 | I14: 0.92 | J14: 1 | K14: 0 | L14: 0 | M14: =IF(J14>1,J14*F14*3&" × "&G14*3&"（"&J14&" 帧横排）",F14*3&" × "&G14*3)
... A63: icon.score | B63: 界面图标 | C63: 顶栏「分数」图标 | D63: P2 | F63: 38 | G63: 38 | H63: 0.5 | I63: 0.5 | J63: 1 | K63: 0 | L63: 0 | M63: =IF(J63>1,J63*F63*3&" × "&G63*3&"（"&J63&" 帧横排）",F63*3&" × "&G63*3)
A65: ※ 图片地址填公开可访问的 https:// 链接（PNG / WebP，透明背景）；也可以不填，直接在游戏页面点「导入美术图片」，把文件名改成资源编号（如 tower.dart.png）一次选多张。
A66: ※ 游戏内宽高以 360 × 600 的画布为单位；出图按 3 倍像素（见最后一列），游戏会缩放到这里填的尺寸。
A67: ※ 锚点是图片里对齐游戏坐标的那一点：0,0 = 左上角，0.5,1 = 底边中点（跑者、装置用脚底中点）。
A68: ※ 帧数 > 1 时，图片是横向排开的序列帧（每帧等宽），按帧率循环播放。跑者、Boss 统一画成「侧面向右跑」，向左时游戏自动水平翻转。
A69: ※ 装置进化图（tower.xxx.p1–p3）在该路线升到 3 级以上并成为主路线时替换基础图；没给就继续用基础图。
A70: ※ 优先级：P1 样板关（先画这些就能完整玩一张图）→ P2 → P3。

Sheet 界面文字
A1: 原文（id，勿改） | B1: 中文 | C1: English | D1: Français
A2: key | B2: zh | C2: en | D2: fr
A3: +30%（满天赋） | B3: +30%（满天赋） | C3: +30% (max talents) | D3: +30 % (talents au max)
A4: 0%（新玩家） | B4: 0%（新玩家） | C4: 0% (new player) | D4: 0 % (nouveau joueur)
A5: 1× 速度 | B5: 1× 速度 | C5: 1× speed | D5: Vitesse 1×
A6: 2× 速度 | B6: 2× 速度 | C6: 2× speed | D6: Vitesse 2×
A7: 3 个 Boss 波每局从 6 位传奇跑者里随机抽：Nox（九命复活）、Aurum（召唤金甲跑者）、Slimo（黏液加速）、Rocco（铁头冲刺）、Chuckles（大笑让装置停工）、Datto（对常用装置产生抗性）。 | B7: 3 个 Boss 波每局从 6 位传奇跑者里随机抽：Nox（九命复活）、Aurum（召唤金甲跑者）、Slimo（黏液加速）、Rocco（铁头冲刺）、Chuckles（大笑让装置停工）、Datto（对常用装置产生抗性）。 | C7: Each run draws 3 bosses from 6 legendary runners: Nox (nine lives), Aurum (summons golden runners), Slimo (slime boost), Rocco (headstrong dash), Chuckles (laughter jams devices), Datto (adapts to your most-used device). | D7: Chaque partie tire 3 boss parmi 6 coureurs légendaires : Nox (neuf vies), Aurum (invoque des coureurs dorés), Slimo (bave accélérante), Rocco (charge tête baissée), Chuckles (son rire bloque les dispositifs), Datto (s’adapte à ton dispositif favori).
A8: 6 种装置：易拉罐投手（单体）、香蕉皮投手（范围滑倒）、洒水器（减速、冻结）、鞋盒无人机（全图空投）、广场舞音响（神曲连锁传播）、宝石发射器（红黄蓝三种宝石）。每种 3 条路线、每条 5 级；主路线可升满，次路线最多 2 级。 | B8: 6 种装置：易拉罐投手（单体）、香蕉皮投手（范围滑倒）、洒水器（减速、冻结）、鞋盒无人机（全图空投）、广场舞音响（神曲连锁传播）、宝石发射器（红黄蓝三种宝石）。每种 3 条路线、每条 5 级；主路线可升满，次路线最多 2 级。 | C8: 6 devices: Can Thrower (single target), Banana Peeler (area slip), Sprinkler (slow, freeze), Shoebox Drone (map-wide drop), Dance Speaker (chain earworm), Gem Launcher (ruby, topaz, sapphire). Each has 3 paths of 5 tiers; the main path can max out, the secondary stops at tier 2. | D8: 6 dispositifs : Lanceur de canettes (cible unique), Lanceur de peaux de banane (glissade de zone), Arroseur (ralentit, gèle), Drone à boîtes (largage sur toute la carte), Enceinte de danse (tube viral en chaîne), Lance-gemmes (rubis, topaze, saphir). Chacun a 3 voies de 5 niveaux ; la voie principale peut être maximisée, la secondaire s’arrête au niveau 2.
A9: Boss 波 | B9: Boss 波 | C9: Boss wave | D9: Vague de boss
A10: Boss：{n}（{t}） | B10: Boss：{n}（{t}） | C10: Boss: {n} ({t}) | D10: Boss : {n} ({t})
A11: Nox 九命 | B11: Nox 九命 | C11: Nox: Nine Lives | D11: Nox : neuf vies
A12: {n} 名跑者 | B12: {n} 名跑者 | C12: {n} runners | D12: {n} coureurs
... A282: 对{x}无效 | B282: 对{x}无效 | C282: No effect on {x} | D282: Sans effet sur {x}
A284: ※ 花括号里的 {n}、{x} 等是占位符，翻译时要原样保留。

Sheet 效果语法
A1: 写法 / 属性 | B1: 说明
A3: 写法 | B3: 多个效果用分号隔开，例如：dmg+=2; armor=1
A4: += | B4: 增加：dmg+=1
A5: *= | B5: 乘以：rate*=0.8（出手间隔 ×0.8，即变快 20%）
A6: = | B6: 设为：stun=0.6
A7: >= | B7: 至少为：armor>=0.6
A9: 属性 | B9: 含义
A10: dmg | B10: 效果（伤害）
A11: rate | B11: 出手间隔（秒，越小越快）
A12: range | B12: 射程
A13: rad | B13: 香蕉皮范围半径
A14: slow | B14: 减速比例
... A54: heat | B54: 矿机热风每秒效果

Sheet 数值体检·波次
A1: 波次 | B1: 总人数 | C1: 有效总体力 | D1: 本波劝退可得 GST | E1: 开打前累计可用 GST | F1: 预计时长（秒） | G1: 需要的输出（HP/秒） | H1: 预计可用输出（HP/秒） | I1: 压力系数 = 需要 ÷ 可用 | J1: 较上一波
M2: 假设参数（蓝字可改）
A3: =波次!A3 | B3: =波次!M3 | C3: =波次!B3*波次!D3+波次!C3*波次!E3*$N$3+波次!F3*波次!G3+(波次!I3*INDEX(全局!$B:$B,MATCH("hpRain",全局!$A:$A,0))+波次!J3*INDEX(全局!$B:$B,MATCH("hpHop",全局!$A:$A,0))+波次!K3*INDEX(全局!$B:$B,MATCH("hpPhones",全局!$A:$A,0)))*波次!D3+波次!L3*波次!E3*INDEX(全局!$B:$B,MATCH("hpWhale",全局!$A:$A,0))*$N$4 | D3: =波次!B3*INDEX(敌人!$G:$G,MATCH("norm",敌人!$A:$A,0))+波次!C3*INDEX(敌人!$G:$G,MATCH("arm",敌人!$A:$A,0))+波次!F3*INDEX(敌人!$G:$G,MATCH("boss",敌人!$A:$A,0))+波次!I3*INDEX(敌人!$G:$G,MATCH("rain",敌人!$A:$A,0))+波次!J3*INDEX(敌人!$G:$G,MATCH("hop",敌人!$A:$A,0))+波次!K3*INDEX(敌人!$G:$G,MATCH("phones",敌人!$A:$A,0))+波次!L3*INDEX(敌人!$G:$G,MATCH("whale",敌人!$A:$A,0)) | E3: =INDEX(全局!$B:$B,MATCH("startGold",全局!$A:$A,0)) | F3: =B3*MAX(INDEX(全局!$B:$B,MATCH("spawnMin",全局!$A:$A,0)),INDEX(全局!$B:$B,MATCH("spawnBase",全局!$A:$A,0))-A3*INDEX(全局!$B:$B,MATCH("spawnPerWave",全局!$A:$A,0)))+$N$5/$N$6 | G3: =C3/F3 | H3: =E3*$N$7 | I3: =G3/H3 | M3: 耐力跑者体力折算 | N3: 1.6 | O3: 耐力跑者对大多数装置有减免，按 ×1.6 算有效体力
A4: =波次!A4 | B4: =波次!M4 | C4: =波次!B4*波次!D4+波次!C4*波次!E4*$N$3+波次!F4*波次!G4+(波次!I4*INDEX(全局!$B:$B,MATCH("hpRain",全局!$A:$A,0))+波次!J4*INDEX(全局!$B:$B,MATCH("hpHop",全局!$A:$A,0))+波次!K4*INDEX(全局!$B:$B,MATCH("hpPhones",全局!$A:$A,0)))*波次!D4+波次!L4*波次!E4*INDEX(全局!$B:$B,MATCH("hpWhale",全局!$A:$A,0))*$N$4 | D4: =波次!B4*INDEX(敌人!$G:$G,MATCH("norm",敌人!$A:$A,0))+波次!C4*INDEX(敌人!$G:$G,MATCH("arm",敌人!$A:$A,0))+波次!F4*INDEX(敌人!$G:$G,MATCH("boss",敌人!$A:$A,0))+波次!I4*INDEX(敌人!$G:$G,MATCH("rain",敌人!$A:$A,0))+波次!J4*INDEX(敌人!$G:$G,MATCH("hop",敌人!$A:$A,0))+波次!K4*INDEX(敌人!$G:$G,MATCH("phones",敌人!$A:$A,0))+波次!L4*INDEX(敌人!$G:$G,MATCH("whale",敌人!$A:$A,0)) | E4: =E3+D3+INDEX(全局!$B:$B,MATCH("waveReward",全局!$A:$A,0)) | F4: =B4*MAX(INDEX(全局!$B:$B,MATCH("spawnMin",全局!$A:$A,0)),INDEX(全局!$B:$B,MATCH("spawnBase",全局!$A:$A,0))-A4*INDEX(全局!$B:$B,MATCH("spawnPerWave",全局!$A:$A,0)))+$N$5/$N$6 | G4: =C4/F4 | H4: =E4*$N$7 | I4: =G4/H4 | J4: =I4/I3-1 | M4: 巨鲸体力折算 | N4: 1.5 | O4: 巨鲸削弱小伤害，按 ×1.5 算有效体力
A5: =波次!A5 | B5: =波次!M5 | C5: =波次!B5*波次!D5+波次!C5*波次!E5*$N$3+波次!F5*波次!G5+(波次!I5*INDEX(全局!$B:$B,MATCH("hpRain",全局!$A:$A,0))+波次!J5*INDEX(全局!$B:$B,MATCH("hpHop",全局!$A:$A,0))+波次!K5*INDEX(全局!$B:$B,MATCH("hpPhones",全局!$A:$A,0)))*波次!D5+波次!L5*波次!E5*INDEX(全局!$B:$B,MATCH("hpWhale",全局!$A:$A,0))*$N$4 | D5: =波次!B5*INDEX(敌人!$G:$G,MATCH("norm",敌人!$A:$A,0))+波次!C5*INDEX(敌人!$G:$G,MATCH("arm",敌人!$A:$A,0))+波次!F5*INDEX(敌人!$G:$G,MATCH("boss",敌人!$A:$A,0))+波次!I5*INDEX(敌人!$G:$G,MATCH("rain",敌人!$A:$A,0))+波次!J5*INDEX(敌人!$G:$G,MATCH("hop",敌人!$A:$A,0))+波次!K5*INDEX(敌人!$G:$G,MATCH("phones",敌人!$A:$A,0))+波次!L5*INDEX(敌人!$G:$G,MATCH("whale",敌人!$A:$A,0)) | E5: =E4+D4+INDEX(全局!$B:$B,MATCH("waveReward",全局!$A:$A,0)) | F5: =B5*MAX(INDEX(全局!$B:$B,MATCH("spawnMin",全局!$A:$A,0)),INDEX(全局!$B:$B,MATCH("spawnBase",全局!$A:$A,0))-A5*INDEX(全局!$B:$B,MATCH("spawnPerWave",全局!$A:$A,0)))+$N$5/$N$6 | G5: =C5/F5 | H5: =E5*$N$7 | I5: =G5/H5 | J5: =I5/I4-1 | M5: 跑道长度（像素） | N5: 1500 | O5: 经典跑道大约 1500
A6: =波次!A6 | B6: =波次!M6 | C6: =波次!B6*波次!D6+波次!C6*波次!E6*$N$3+波次!F6*波次!G6+(波次!I6*INDEX(全局!$B:$B,MATCH("hpRain",全局!$A:$A,0))+波次!J6*INDEX(全局!$B:$B,MATCH("hpHop",全局!$A:$A,0))+波次!K6*INDEX(全局!$B:$B,MATCH("hpPhones",全局!$A:$A,0)))*波次!D6+波次!L6*波次!E6*INDEX(全局!$B:$B,MATCH("hpWhale",全局!$A:$A,0))*$N$4 | D6: =波次!B6*INDEX(敌人!$G:$G,MATCH("norm",敌人!$A:$A,0))+波次!C6*INDEX(敌人!$G:$G,MATCH("arm",敌人!$A:$A,0))+波次!F6*INDEX(敌人!$G:$G,MATCH("boss",敌人!$A:$A,0))+波次!I6*INDEX(敌人!$G:$G,MATCH("rain",敌人!$A:$A,0))+波次!J6*INDEX(敌人!$G:$G,MATCH("hop",敌人!$A:$A,0))+波次!K6*INDEX(敌人!$G:$G,MATCH("phones",敌人!$A:$A,0))+波次!L6*INDEX(敌人!$G:$G,MATCH("whale",敌人!$A:$A,0)) | E6: =E5+D5+INDEX(全局!$B:$B,MATCH("waveReward",全局!$A:$A,0)) | F6: =B6*MAX(INDEX(全局!$B:$B,MATCH("spawnMin",全局!$A:$A,0)),INDEX(全局!$B:$B,MATCH("spawnBase",全局!$A:$A,0))-A6*INDEX(全局!$B:$B,MATCH("spawnPerWave",全局!$A:$A,0)))+$N$5/$N$6 | G6: =C6/F6 | H6: =E6*$N$7 | I6: =G6/H6 | J6: =I6/I5-1 | M6: 平均移速 | N6: =INDEX(敌人!$F:$F,MATCH("norm",敌人!$A:$A,0)) | O6: 取慢跑者移速
A7: =波次!A7 | B7: =波次!M7 | C7: =波次!B7*波次!D7+波次!C7*波次!E7*$N$3+波次!F7*波次!G7+(波次!I7*INDEX(全局!$B:$B,MATCH("hpRain",全局!$A:$A,0))+波次!J7*INDEX(全局!$B:$B,MATCH("hpHop",全局!$A:$A,0))+波次!K7*INDEX(全局!$B:$B,MATCH("hpPhones",全局!$A:$A,0)))*波次!D7+波次!L7*波次!E7*INDEX(全局!$B:$B,MATCH("hpWhale",全局!$A:$A,0))*$N$4 | D7: =波次!B7*INDEX(敌人!$G:$G,MATCH("norm",敌人!$A:$A,0))+波次!C7*INDEX(敌人!$G:$G,MATCH("arm",敌人!$A:$A,0))+波次!F7*INDEX(敌人!$G:$G,MATCH("boss",敌人!$A:$A,0))+波次!I7*INDEX(敌人!$G:$G,MATCH("rain",敌人!$A:$A,0))+波次!J7*INDEX(敌人!$G:$G,MATCH("hop",敌人!$A:$A,0))+波次!K7*INDEX(敌人!$G:$G,MATCH("phones",敌人!$A:$A,0))+波次!L7*INDEX(敌人!$G:$G,MATCH("whale",敌人!$A:$A,0)) | E7: =E6+D6+INDEX(全局!$B:$B,MATCH("waveReward",全局!$A:$A,0)) | F7: =B7*MAX(INDEX(全局!$B:$B,MATCH("spawnMin",全局!$A:$A,0)),INDEX(全局!$B:$B,MATCH("spawnBase",全局!$A:$A,0))-A7*INDEX(全局!$B:$B,MATCH("spawnPerWave",全局!$A:$A,0)))+$N$5/$N$6 | G7: =C7/F7 | H7: =E7*$N$7 | I7: =G7/H7 | J7: =I7/I6-1 | M7: 每 GST 可换来的输出（HP/秒） | N7: 0.025 | O7: 用「数值体检·装置」里基础装置的平均值粗估；投入越多、越靠后的升级越不划算
A8: =波次!A8 | B8: =波次!M8 | C8: =波次!B8*波次!D8+波次!C8*波次!E8*$N$3+波次!F8*波次!G8+(波次!I8*INDEX(全局!$B:$B,MATCH("hpRain",全局!$A:$A,0))+波次!J8*INDEX(全局!$B:$B,MATCH("hpHop",全局!$A:$A,0))+波次!K8*INDEX(全局!$B:$B,MATCH("hpPhones",全局!$A:$A,0)))*波次!D8+波次!L8*波次!E8*INDEX(全局!$B:$B,MATCH("hpWhale",全局!$A:$A,0))*$N$4 | D8: =波次!B8*INDEX(敌人!$G:$G,MATCH("norm",敌人!$A:$A,0))+波次!C8*INDEX(敌人!$G:$G,MATCH("arm",敌人!$A:$A,0))+波次!F8*INDEX(敌人!$G:$G,MATCH("boss",敌人!$A:$A,0))+波次!I8*INDEX(敌人!$G:$G,MATCH("rain",敌人!$A:$A,0))+波次!J8*INDEX(敌人!$G:$G,MATCH("hop",敌人!$A:$A,0))+波次!K8*INDEX(敌人!$G:$G,MATCH("phones",敌人!$A:$A,0))+波次!L8*INDEX(敌人!$G:$G,MATCH("whale",敌人!$A:$A,0)) | E8: =E7+D7+INDEX(全局!$B:$B,MATCH("waveReward",全局!$A:$A,0)) | F8: =B8*MAX(INDEX(全局!$B:$B,MATCH("spawnMin",全局!$A:$A,0)),INDEX(全局!$B:$B,MATCH("spawnBase",全局!$A:$A,0))-A8*INDEX(全局!$B:$B,MATCH("spawnPerWave",全局!$A:$A,0)))+$N$5/$N$6 | G8: =C8/F8 | H8: =E8*$N$7 | I8: =G8/H8 | J8: =I8/I7-1 | M8: 压力系数：上限 | N8: 0.85 | O8: 超过就标红（按机器人实测校准：现有 15 波在 1.4 倍体力下仍能通关）
A9: =波次!A9 | B9: =波次!M9 | C9: =波次!B9*波次!D9+波次!C9*波次!E9*$N$3+波次!F9*波次!G9+(波次!I9*INDEX(全局!$B:$B,MATCH("hpRain",全局!$A:$A,0))+波次!J9*INDEX(全局!$B:$B,MATCH("hpHop",全局!$A:$A,0))+波次!K9*INDEX(全局!$B:$B,MATCH("hpPhones",全局!$A:$A,0)))*波次!D9+波次!L9*波次!E9*INDEX(全局!$B:$B,MATCH("hpWhale",全局!$A:$A,0))*$N$4 | D9: =波次!B9*INDEX(敌人!$G:$G,MATCH("norm",敌人!$A:$A,0))+波次!C9*INDEX(敌人!$G:$G,MATCH("arm",敌人!$A:$A,0))+波次!F9*INDEX(敌人!$G:$G,MATCH("boss",敌人!$A:$A,0))+波次!I9*INDEX(敌人!$G:$G,MATCH("rain",敌人!$A:$A,0))+波次!J9*INDEX(敌人!$G:$G,MATCH("hop",敌人!$A:$A,0))+波次!K9*INDEX(敌人!$G:$G,MATCH("phones",敌人!$A:$A,0))+波次!L9*INDEX(敌人!$G:$G,MATCH("whale",敌人!$A:$A,0)) | E9: =E8+D8+INDEX(全局!$B:$B,MATCH("waveReward",全局!$A:$A,0)) | F9: =B9*MAX(INDEX(全局!$B:$B,MATCH("spawnMin",全局!$A:$A,0)),INDEX(全局!$B:$B,MATCH("spawnBase",全局!$A:$A,0))-A9*INDEX(全局!$B:$B,MATCH("spawnPerWave",全局!$A:$A,0)))+$N$5/$N$6 | G9: =C9/F9 | H9: =E9*$N$7 | I9: =G9/H9 | J9: =I9/I8-1 | M9: 压力系数：下限 | N9: 0.25 | O9: 低于就标黄，太轻松
A10: =波次!A10 | B10: =波次!M10 | C10: =波次!B10*波次!D10+波次!C10*波次!E10*$N$3+波次!F10*波次!G10+(波次!I10*INDEX(全局!$B:$B,MATCH("hpRain",全局!$A:$A,0))+波次!J10*INDEX(全局!$B:$B,MATCH("hpHop",全局!$A:$A,0))+波次!K10*INDEX(全局!$B:$B,MATCH("hpPhones",全局!$A:$A,0)))*波次!D10+波次!L10*波次!E10*INDEX(全局!$B:$B,MATCH("hpWhale",全局!$A:$A,0))*$N$4 | D10: =波次!B10*INDEX(敌人!$G:$G,MATCH("norm",敌人!$A:$A,0))+波次!C10*INDEX(敌人!$G:$G,MATCH("arm",敌人!$A:$A,0))+波次!F10*INDEX(敌人!$G:$G,MATCH("boss",敌人!$A:$A,0))+波次!I10*INDEX(敌人!$G:$G,MATCH("rain",敌人!$A:$A,0))+波次!J10*INDEX(敌人!$G:$G,MATCH("hop",敌人!$A:$A,0))+波次!K10*INDEX(敌人!$G:$G,MATCH("phones",敌人!$A:$A,0))+波次!L10*INDEX(敌人!$G:$G,MATCH("whale",敌人!$A:$A,0)) | E10: =E9+D9+INDEX(全局!$B:$B,MATCH("waveReward",全局!$A:$A,0)) | F10: =B10*MAX(INDEX(全局!$B:$B,MATCH("spawnMin",全局!$A:$A,0)),INDEX(全局!$B:$B,MATCH("spawnBase",全局!$A:$A,0))-A10*INDEX(全局!$B:$B,MATCH("spawnPerWave",全局!$A:$A,0)))+$N$5/$N$6 | G10: =C10/F10 | H10: =E10*$N$7 | I10: =G10/H10 | J10: =I10/I9-1
A11: =波次!A11 | B11: =波次!M11 | C11: =波次!B11*波次!D11+波次!C11*波次!E11*$N$3+波次!F11*波次!G11+(波次!I11*INDEX(全局!$B:$B,MATCH("hpRain",全局!$A:$A,0))+波次!J11*INDEX(全局!$B:$B,MATCH("hpHop",全局!$A:$A,0))+波次!K11*INDEX(全局!$B:$B,MATCH("hpPhones",全局!$A:$A,0)))*波次!D11+波次!L11*波次!E11*INDEX(全局!$B:$B,MATCH("hpWhale",全局!$A:$A,0))*$N$4 | D11: =波次!B11*INDEX(敌人!$G:$G,MATCH("norm",敌人!$A:$A,0))+波次!C11*INDEX(敌人!$G:$G,MATCH("arm",敌人!$A:$A,0))+波次!F11*INDEX(敌人!$G:$G,MATCH("boss",敌人!$A:$A,0))+波次!I11*INDEX(敌人!$G:$G,MATCH("rain",敌人!$A:$A,0))+波次!J11*INDEX(敌人!$G:$G,MATCH("hop",敌人!$A:$A,0))+波次!K11*INDEX(敌人!$G:$G,MATCH("phones",敌人!$A:$A,0))+波次!L11*INDEX(敌人!$G:$G,MATCH("whale",敌人!$A:$A,0)) | E11: =E10+D10+INDEX(全局!$B:$B,MATCH("waveReward",全局!$A:$A,0)) | F11: =B11*MAX(INDEX(全局!$B:$B,MATCH("spawnMin",全局!$A:$A,0)),INDEX(全局!$B:$B,MATCH("spawnBase",全局!$A:$A,0))-A11*INDEX(全局!$B:$B,MATCH("spawnPerWave",全局!$A:$A,0)))+$N$5/$N$6 | G11: =C11/F11 | H11: =E11*$N$7 | I11: =G11/H11 | J11: =I11/I10-1
A12: =波次!A12 | B12: =波次!M12 | C12: =波次!B12*波次!D12+波次!C12*波次!E12*$N$3+波次!F12*波次!G12+(波次!I12*INDEX(全局!$B:$B,MATCH("hpRain",全局!$A:$A,0))+波次!J12*INDEX(全局!$B:$B,MATCH("hpHop",全局!$A:$A,0))+波次!K12*INDEX(全局!$B:$B,MATCH("hpPhones",全局!$A:$A,0)))*波次!D12+波次!L12*波次!E12*INDEX(全局!$B:$B,MATCH("hpWhale",全局!$A:$A,0))*$N$4 | D12: =波次!B12*INDEX(敌人!$G:$G,MATCH("norm",敌人!$A:$A,0))+波次!C12*INDEX(敌人!$G:$G,MATCH("arm",敌人!$A:$A,0))+波次!F12*INDEX(敌人!$G:$G,MATCH("boss",敌人!$A:$A,0))+波次!I12*INDEX(敌人!$G:$G,MATCH("rain",敌人!$A:$A,0))+波次!J12*INDEX(敌人!$G:$G,MATCH("hop",敌人!$A:$A,0))+波次!K12*INDEX(敌人!$G:$G,MATCH("phones",敌人!$A:$A,0))+波次!L12*INDEX(敌人!$G:$G,MATCH("whale",敌人!$A:$A,0)) | E12: =E11+D11+INDEX(全局!$B:$B,MATCH("waveReward",全局!$A:$A,0)) | F12: =B12*MAX(INDEX(全局!$B:$B,MATCH("spawnMin",全局!$A:$A,0)),INDEX(全局!$B:$B,MATCH("spawnBase",全局!$A:$A,0))-A12*INDEX(全局!$B:$B,MATCH("spawnPerWave",全局!$A:$A,0)))+$N$5/$N$6 | G12: =C12/F12 | H12: =E12*$N$7 | I12: =G12/H12 | J12: =I12/I11-1
A13: =波次!A13 | B13: =波次!M13 | C13: =波次!B13*波次!D13+波次!C13*波次!E13*$N$3+波次!F13*波次!G13+(波次!I13*INDEX(全局!$B:$B,MATCH("hpRain",全局!$A:$A,0))+波次!J13*INDEX(全局!$B:$B,MATCH("hpHop",全局!$A:$A,0))+波次!K13*INDEX(全局!$B:$B,MATCH("hpPhones",全局!$A:$A,0)))*波次!D13+波次!L13*波次!E13*INDEX(全局!$B:$B,MATCH("hpWhale",全局!$A:$A,0))*$N$4 | D13: =波次!B13*INDEX(敌人!$G:$G,MATCH("norm",敌人!$A:$A,0))+波次!C13*INDEX(敌人!$G:$G,MATCH("arm",敌人!$A:$A,0))+波次!F13*INDEX(敌人!$G:$G,MATCH("boss",敌人!$A:$A,0))+波次!I13*INDEX(敌人!$G:$G,MATCH("rain",敌人!$A:$A,0))+波次!J13*INDEX(敌人!$G:$G,MATCH("hop",敌人!$A:$A,0))+波次!K13*INDEX(敌人!$G:$G,MATCH("phones",敌人!$A:$A,0))+波次!L13*INDEX(敌人!$G:$G,MATCH("whale",敌人!$A:$A,0)) | E13: =E12+D12+INDEX(全局!$B:$B,MATCH("waveReward",全局!$A:$A,0)) | F13: =B13*MAX(INDEX(全局!$B:$B,MATCH("spawnMin",全局!$A:$A,0)),INDEX(全局!$B:$B,MATCH("spawnBase",全局!$A:$A,0))-A13*INDEX(全局!$B:$B,MATCH("spawnPerWave",全局!$A:$A,0)))+$N$5/$N$6 | G13: =C13/F13 | H13: =E13*$N$7 | I13: =G13/H13 | J13: =I13/I12-1
A14: =波次!A14 | B14: =波次!M14 | C14: =波次!B14*波次!D14+波次!C14*波次!E14*$N$3+波次!F14*波次!G14+(波次!I14*INDEX(全局!$B:$B,MATCH("hpRain",全局!$A:$A,0))+波次!J14*INDEX(全局!$B:$B,MATCH("hpHop",全局!$A:$A,0))+波次!K14*INDEX(全局!$B:$B,MATCH("hpPhones",全局!$A:$A,0)))*波次!D14+波次!L14*波次!E14*INDEX(全局!$B:$B,MATCH("hpWhale",全局!$A:$A,0))*$N$4 | D14: =波次!B14*INDEX(敌人!$G:$G,MATCH("norm",敌人!$A:$A,0))+波次!C14*INDEX(敌人!$G:$G,MATCH("arm",敌人!$A:$A,0))+波次!F14*INDEX(敌人!$G:$G,MATCH("boss",敌人!$A:$A,0))+波次!I14*INDEX(敌人!$G:$G,MATCH("rain",敌人!$A:$A,0))+波次!J14*INDEX(敌人!$G:$G,MATCH("hop",敌人!$A:$A,0))+波次!K14*INDEX(敌人!$G:$G,MATCH("phones",敌人!$A:$A,0))+波次!L14*INDEX(敌人!$G:$G,MATCH("whale",敌人!$A:$A,0)) | E14: =E13+D13+INDEX(全局!$B:$B,MATCH("waveReward",全局!$A:$A,0)) | F14: =B14*MAX(INDEX(全局!$B:$B,MATCH("spawnMin",全局!$A:$A,0)),INDEX(全局!$B:$B,MATCH("spawnBase",全局!$A:$A,0))-A14*INDEX(全局!$B:$B,MATCH("spawnPerWave",全局!$A:$A,0)))+$N$5/$N$6 | G14: =C14/F14 | H14: =E14*$N$7 | I14: =G14/H14 | J14: =I14/I13-1
A15: =波次!A15 | B15: =波次!M15 | C15: =波次!B15*波次!D15+波次!C15*波次!E15*$N$3+波次!F15*波次!G15+(波次!I15*INDEX(全局!$B:$B,MATCH("hpRain",全局!$A:$A,0))+波次!J15*INDEX(全局!$B:$B,MATCH("hpHop",全局!$A:$A,0))+波次!K15*INDEX(全局!$B:$B,MATCH("hpPhones",全局!$A:$A,0)))*波次!D15+波次!L15*波次!E15*INDEX(全局!$B:$B,MATCH("hpWhale",全局!$A:$A,0))*$N$4 | D15: =波次!B15*INDEX(敌人!$G:$G,MATCH("norm",敌人!$A:$A,0))+波次!C15*INDEX(敌人!$G:$G,MATCH("arm",敌人!$A:$A,0))+波次!F15*INDEX(敌人!$G:$G,MATCH("boss",敌人!$A:$A,0))+波次!I15*INDEX(敌人!$G:$G,MATCH("rain",敌人!$A:$A,0))+波次!J15*INDEX(敌人!$G:$G,MATCH("hop",敌人!$A:$A,0))+波次!K15*INDEX(敌人!$G:$G,MATCH("phones",敌人!$A:$A,0))+波次!L15*INDEX(敌人!$G:$G,MATCH("whale",敌人!$A:$A,0)) | E15: =E14+D14+INDEX(全局!$B:$B,MATCH("waveReward",全局!$A:$A,0)) | F15: =B15*MAX(INDEX(全局!$B:$B,MATCH("spawnMin",全局!$A:$A,0)),INDEX(全局!$B:$B,MATCH("spawnBase",全局!$A:$A,0))-A15*INDEX(全局!$B:$B,MATCH("spawnPerWave",全局!$A:$A,0)))+$N$5/$N$6 | G15: =C15/F15 | H15: =E15*$N$7 | I15: =G15/H15 | J15: =I15/I14-1
A16: =波次!A16 | B16: =波次!M16 | C16: =波次!B16*波次!D16+波次!C16*波次!E16*$N$3+波次!F16*波次!G16+(波次!I16*INDEX(全局!$B:$B,MATCH("hpRain",全局!$A:$A,0))+波次!J16*INDEX(全局!$B:$B,MATCH("hpHop",全局!$A:$A,0))+波次!K16*INDEX(全局!$B:$B,MATCH("hpPhones",全局!$A:$A,0)))*波次!D16+波次!L16*波次!E16*INDEX(全局!$B:$B,MATCH("hpWhale",全局!$A:$A,0))*$N$4 | D16: =波次!B16*INDEX(敌人!$G:$G,MATCH("norm",敌人!$A:$A,0))+波次!C16*INDEX(敌人!$G:$G,MATCH("arm",敌人!$A:$A,0))+波次!F16*INDEX(敌人!$G:$G,MATCH("boss",敌人!$A:$A,0))+波次!I16*INDEX(敌人!$G:$G,MATCH("rain",敌人!$A:$A,0))+波次!J16*INDEX(敌人!$G:$G,MATCH("hop",敌人!$A:$A,0))+波次!K16*INDEX(敌人!$G:$G,MATCH("phones",敌人!$A:$A,0))+波次!L16*INDEX(敌人!$G:$G,MATCH("whale",敌人!$A:$A,0)) | E16: =E15+D15+INDEX(全局!$B:$B,MATCH("waveReward",全局!$A:$A,0)) | F16: =B16*MAX(INDEX(全局!$B:$B,MATCH("spawnMin",全局!$A:$A,0)),INDEX(全局!$B:$B,MATCH("spawnBase",全局!$A:$A,0))-A16*INDEX(全局!$B:$B,MATCH("spawnPerWave",全局!$A:$A,0)))+$N$5/$N$6 | G16: =C16/F16 | H16: =E16*$N$7 | I16: =G16/H16 | J16: =I16/I15-1
A17: =波次!A17 | B17: =波次!M17 | C17: =波次!B17*波次!D17+波次!C17*波次!E17*$N$3+波次!F17*波次!G17+(波次!I17*INDEX(全局!$B:$B,MATCH("hpRain",全局!$A:$A,0))+波次!J17*INDEX(全局!$B:$B,MATCH("hpHop",全局!$A:$A,0))+波次!K17*INDEX(全局!$B:$B,MATCH("hpPhones",全局!$A:$A,0)))*波次!D17+波次!L17*波次!E17*INDEX(全局!$B:$B,MATCH("hpWhale",全局!$A:$A,0))*$N$4 | D17: =波次!B17*INDEX(敌人!$G:$G,MATCH("norm",敌人!$A:$A,0))+波次!C17*INDEX(敌人!$G:$G,MATCH("arm",敌人!$A:$A,0))+波次!F17*INDEX(敌人!$G:$G,MATCH("boss",敌人!$A:$A,0))+波次!I17*INDEX(敌人!$G:$G,MATCH("rain",敌人!$A:$A,0))+波次!J17*INDEX(敌人!$G:$G,MATCH("hop",敌人!$A:$A,0))+波次!K17*INDEX(敌人!$G:$G,MATCH("phones",敌人!$A:$A,0))+波次!L17*INDEX(敌人!$G:$G,MATCH("whale",敌人!$A:$A,0)) | E17: =E16+D16+INDEX(全局!$B:$B,MATCH("waveReward",全局!$A:$A,0)) | F17: =B17*MAX(INDEX(全局!$B:$B,MATCH("spawnMin",全局!$A:$A,0)),INDEX(全局!$B:$B,MATCH("spawnBase",全局!$A:$A,0))-A17*INDEX(全局!$B:$B,MATCH("spawnPerWave",全局!$A:$A,0)))+$N$5/$N$6 | G17: =C17/F17 | H17: =E17*$N$7 | I17: =G17/H17 | J17: =I17/I16-1
A19: 怎么看：压力系数 = 这一波需要的输出 ÷ 按累计 GST 估出来的可用输出。绿色在目标区间，红色太难，黄色太轻松。
A20: 理想曲线：前几波偏低让玩家站稳，之后缓慢上升；「较上一波」超过 +30% 会标红，代表难度突然跳一大截。
A21: 这是粗估：没算神秘箱卡牌、组合和矿机，所以只看相对走势，不看绝对值。改了「波次」「敌人」「全局」表，这里会自动重算。

Sheet 数值体检·装置
A1: 装置 | B1: 路线（0=基础） | C1: 等级 | D1: 名称 | E1: 本级价格 | F1: 累计花费 | G1: 估算输出（HP/秒） | H1: 每 100 GST 输出 | I1: 比同价多买基础塔（估算） | J1: 本级边际性价比 | K1: 实测：本配置清除体力比例 | L1: 实测：同价基础塔清除比例 | M1: 实测比值 | N1: 功能型效果 | O1: 结论
A3: dart | B3: 0 | C3: 0 | D3: 基础 | E3: 100 | F3: 100 | G3: 2.24 | H3: =G3/F3*100 | I3: =IFERROR((G3/F3)/(SUMIFS($G$3:$G$98,$A$3:$A$98,A3,$B$3:$B$98,0)/SUMIFS($F$3:$F$98,$A$3:$A$98,A3,$B$3:$B$98,0)),"") | J3: =IF(B3=0,1,IF(C3<=1,G3-SUMIFS($G$3:$G$98,$A$3:$A$98,A3,$B$3:$B$98,0),G3-G2)/E3/(SUMIFS($G$3:$G$98,$A$3:$A$98,A3,$B$3:$B$98,0)/SUMIFS($F$3:$F$98,$A$3:$A$98,A3,$B$3:$B$98,0))) | M3: =IF(OR(K3="",L3="",L3=0),"",K3/L3) | O3: =IF(B3=0,"基准",IF(AND(N3<>"",I3<0.85),"功能型：单看输出偏低属正常",IF(I3>=0.85,"划算",IF(I3>=0.65,"略亏：空位紧张时仍值得","偏亏：建议降价或加强"))))
A4: dart | B4: 1 | C4: 1 | D4: 加料汽水罐 | E4: 70 | F4: 170 | G4: 4.48 | H4: =G4/F4*100 | I4: =IFERROR((G4/F4)/(SUMIFS($G$3:$G$98,$A$3:$A$98,A4,$B$3:$B$98,0)/SUMIFS($F$3:$F$98,$A$3:$A$98,A4,$B$3:$B$98,0)),"") | J4: =IF(B4=0,1,IF(C4<=1,G4-SUMIFS($G$3:$G$98,$A$3:$A$98,A4,$B$3:$B$98,0),G4-G3)/E4/(SUMIFS($G$3:$G$98,$A$3:$A$98,A4,$B$3:$B$98,0)/SUMIFS($F$3:$F$98,$A$3:$A$98,A4,$B$3:$B$98,0))) | K4: 0.449 | L4: 0.36 | M4: =IF(OR(K4="",L4="",L4=0),"",K4/L4) | O4: =IF(B4=0,"基准",IF(AND(N4<>"",I4<0.85),"功能型：单看输出偏低属正常",IF(I4>=0.85,"划算",IF(I4>=0.65,"略亏：空位紧张时仍值得","偏亏：建议降价或加强"))))
A5: dart | B5: 1 | C5: 2 | D5: 铁皮罐 | E5: 120 | F5: 290 | G5: 4.48 | H5: =G5/F5*100 | I5: =IFERROR((G5/F5)/(SUMIFS($G$3:$G$98,$A$3:$A$98,A5,$B$3:$B$98,0)/SUMIFS($F$3:$F$98,$A$3:$A$98,A5,$B$3:$B$98,0)),"") | J5: =IF(B5=0,1,IF(C5<=1,G5-SUMIFS($G$3:$G$98,$A$3:$A$98,A5,$B$3:$B$98,0),G5-G4)/E5/(SUMIFS($G$3:$G$98,$A$3:$A$98,A5,$B$3:$B$98,0)/SUMIFS($F$3:$F$98,$A$3:$A$98,A5,$B$3:$B$98,0))) | K5: 0.456 | L5: 0.565 | M5: =IF(OR(K5="",L5="",L5=0),"",K5/L5) | N5: 破甲 | O5: =IF(B5=0,"基准",IF(AND(N5<>"",I5<0.85),"功能型：单看输出偏低属正常",IF(I5>=0.85,"划算",IF(I5>=0.65,"略亏：空位紧张时仍值得","偏亏：建议降价或加强"))))
A6: dart | B6: 1 | C6: 3 | D6: 实心铁罐 | E6: 260 | F6: 550 | G6: 11.2 | H6: =G6/F6*100 | I6: =IFERROR((G6/F6)/(SUMIFS($G$3:$G$98,$A$3:$A$98,A6,$B$3:$B$98,0)/SUMIFS($F$3:$F$98,$A$3:$A$98,A6,$B$3:$B$98,0)),"") | J6: =IF(B6=0,1,IF(C6<=1,G6-SUMIFS($G$3:$G$98,$A$3:$A$98,A6,$B$3:$B$98,0),G6-G5)/E6/(SUMIFS($G$3:$G$98,$A$3:$A$98,A6,$B$3:$B$98,0)/SUMIFS($F$3:$F$98,$A$3:$A$98,A6,$B$3:$B$98,0))) | K6: 0.785 | L6: 0.795 | M6: =IF(OR(K6="",L6="",L6=0),"",K6/L6) | N6: 破甲 | O6: =IF(B6=0,"基准",IF(AND(N6<>"",I6<0.85),"功能型：单看输出偏低属正常",IF(I6>=0.85,"划算",IF(I6>=0.65,"略亏：空位紧张时仍值得","偏亏：建议降价或加强"))))
A7: dart | B7: 1 | C7: 4 | D7: 罐头炮 | E7: 600 | F7: 1150 | G7: 22.4 | H7: =G7/F7*100 | I7: =IFERROR((G7/F7)/(SUMIFS($G$3:$G$98,$A$3:$A$98,A7,$B$3:$B$98,0)/SUMIFS($F$3:$F$98,$A$3:$A$98,A7,$B$3:$B$98,0)),"") | J7: =IF(B7=0,1,IF(C7<=1,G7-SUMIFS($G$3:$G$98,$A$3:$A$98,A7,$B$3:$B$98,0),G7-G6)/E7/(SUMIFS($G$3:$G$98,$A$3:$A$98,A7,$B$3:$B$98,0)/SUMIFS($F$3:$F$98,$A$3:$A$98,A7,$B$3:$B$98,0))) | K7: 1 | L7: 1 | M7: =IF(OR(K7="",L7="",L7=0),"",K7/L7) | N7: 对 Boss | O7: =IF(B7=0,"基准",IF(AND(N7<>"",I7<0.85),"功能型：单看输出偏低属正常",IF(I7>=0.85,"划算",IF(I7>=0.65,"略亏：空位紧张时仍值得","偏亏：建议降价或加强"))))
A8: dart | B8: 1 | C8: 5 | D8: 大桶可乐 | E8: 1400 | F8: 2550 | G8: 53.76 | H8: =G8/F8*100 | I8: =IFERROR((G8/F8)/(SUMIFS($G$3:$G$98,$A$3:$A$98,A8,$B$3:$B$98,0)/SUMIFS($F$3:$F$98,$A$3:$A$98,A8,$B$3:$B$98,0)),"") | J8: =IF(B8=0,1,IF(C8<=1,G8-SUMIFS($G$3:$G$98,$A$3:$A$98,A8,$B$3:$B$98,0),G8-G7)/E8/(SUMIFS($G$3:$G$98,$A$3:$A$98,A8,$B$3:$B$98,0)/SUMIFS($F$3:$F$98,$A$3:$A$98,A8,$B$3:$B$98,0))) | M8: =IF(OR(K8="",L8="",L8=0),"",K8/L8) | O8: =IF(B8=0,"基准",IF(AND(N8<>"",I8<0.85),"功能型：单看输出偏低属正常",IF(I8>=0.85,"划算",IF(I8>=0.65,"略亏：空位紧张时仍值得","偏亏：建议降价或加强"))))
A9: dart | B9: 2 | C9: 1 | D9: 快手 | E9: 40 | F9: 140 | G9: 2.99 | H9: =G9/F9*100 | I9: =IFERROR((G9/F9)/(SUMIFS($G$3:$G$98,$A$3:$A$98,A9,$B$3:$B$98,0)/SUMIFS($F$3:$F$98,$A$3:$A$98,A9,$B$3:$B$98,0)),"") | J9: =IF(B9=0,1,IF(C9<=1,G9-SUMIFS($G$3:$G$98,$A$3:$A$98,A9,$B$3:$B$98,0),G9-G8)/E9/(SUMIFS($G$3:$G$98,$A$3:$A$98,A9,$B$3:$B$98,0)/SUMIFS($F$3:$F$98,$A$3:$A$98,A9,$B$3:$B$98,0))) | K9: 0.255 | L9: 0.306 | M9: =IF(OR(K9="",L9="",L9=0),"",K9/L9) | O9: =IF(B9=0,"基准",IF(AND(N9<>"",I9<0.85),"功能型：单看输出偏低属正常",IF(I9>=0.85,"划算",IF(I9>=0.65,"略亏：空位紧张时仍值得","偏亏：建议降价或加强"))))
A10: dart | B10: 2 | C10: 2 | D10: 双手投 | E10: 70 | F10: 210 | G10: 3.98 | H10: =G10/F10*100 | I10: =IFERROR((G10/F10)/(SUMIFS($G$3:$G$98,$A$3:$A$98,A10,$B$3:$B$98,0)/SUMIFS($F$3:$F$98,$A$3:$A$98,A10,$B$3:$B$98,0)),"") | J10: =IF(B10=0,1,IF(C10<=1,G10-SUMIFS($G$3:$G$98,$A$3:$A$98,A10,$B$3:$B$98,0),G10-G9)/E10/(SUMIFS($G$3:$G$98,$A$3:$A$98,A10,$B$3:$B$98,0)/SUMIFS($F$3:$F$98,$A$3:$A$98,A10,$B$3:$B$98,0))) | K10: 0.296 | L10: 0.43 | M10: =IF(OR(K10="",L10="",L10=0),"",K10/L10) | O10: =IF(B10=0,"基准",IF(AND(N10<>"",I10<0.85),"功能型：单看输出偏低属正常",IF(I10>=0.85,"划算",IF(I10>=0.65,"略亏：空位紧张时仍值得","偏亏：建议降价或加强"))))
A11: dart | B11: 2 | C11: 3 | D11: 三连投 | E11: 280 | F11: 490 | G11: 11.95 | H11: =G11/F11*100 | I11: =IFERROR((G11/F11)/(SUMIFS($G$3:$G$98,$A$3:$A$98,A11,$B$3:$B$98,0)/SUMIFS($F$3:$F$98,$A$3:$A$98,A11,$B$3:$B$98,0)),"") | J11: =IF(B11=0,1,IF(C11<=1,G11-SUMIFS($G$3:$G$98,$A$3:$A$98,A11,$B$3:$B$98,0),G11-G10)/E11/(SUMIFS($G$3:$G$98,$A$3:$A$98,A11,$B$3:$B$98,0)/SUMIFS($F$3:$F$98,$A$3:$A$98,A11,$B$3:$B$98,0))) | K11: 0.772 | L11: 0.763 | M11: =IF(OR(K11="",L11="",L11=0),"",K11/L11) | O11: =IF(B11=0,"基准",IF(AND(N11<>"",I11<0.85),"功能型：单看输出偏低属正常",IF(I11>=0.85,"划算",IF(I11>=0.65,"略亏：空位紧张时仍值得","偏亏：建议降价或加强"))))
A12: dart | B12: 2 | C12: 4 | D12: 自动投罐机 | E12: 650 | F12: 1140 | G12: 23.89 | H12: =G12/F12*100 | I12: =IFERROR((G12/F12)/(SUMIFS($G$3:$G$98,$A$3:$A$98,A12,$B$3:$B$98,0)/SUMIFS($F$3:$F$98,$A$3:$A$98,A12,$B$3:$B$98,0)),"") | J12: =IF(B12=0,1,IF(C12<=1,G12-SUMIFS($G$3:$G$98,$A$3:$A$98,A12,$B$3:$B$98,0),G12-G11)/E12/(SUMIFS($G$3:$G$98,$A$3:$A$98,A12,$B$3:$B$98,0)/SUMIFS($F$3:$F$98,$A$3:$A$98,A12,$B$3:$B$98,0))) | K12: 0.921 | L12: 1 | M12: =IF(OR(K12="",L12="",L12=0),"",K12/L12) | O12: =IF(B12=0,"基准",IF(AND(N12<>"",I12<0.85),"功能型：单看输出偏低属正常",IF(I12>=0.85,"划算",IF(I12>=0.65,"略亏：空位紧张时仍值得","偏亏：建议降价或加强"))))
A13: dart | B13: 2 | C13: 5 | D13: 罐头暴雨 | E13: 1500 | F13: 2640 | G13: 66.52 | H13: =G13/F13*100 | I13: =IFERROR((G13/F13)/(SUMIFS($G$3:$G$98,$A$3:$A$98,A13,$B$3:$B$98,0)/SUMIFS($F$3:$F$98,$A$3:$A$98,A13,$B$3:$B$98,0)),"") | J13: =IF(B13=0,1,IF(C13<=1,G13-SUMIFS($G$3:$G$98,$A$3:$A$98,A13,$B$3:$B$98,0),G13-G12)/E13/(SUMIFS($G$3:$G$98,$A$3:$A$98,A13,$B$3:$B$98,0)/SUMIFS($F$3:$F$98,$A$3:$A$98,A13,$B$3:$B$98,0))) | M13: =IF(OR(K13="",L13="",L13=0),"",K13/L13) | O13: =IF(B13=0,"基准",IF(AND(N13<>"",I13<0.85),"功能型：单看输出偏低属正常",IF(I13>=0.85,"划算",IF(I13>=0.65,"略亏：空位紧张时仍值得","偏亏：建议降价或加强"))))
A14: dart | B14: 3 | C14: 1 | D14: 远投 | E14: 50 | F14: 150 | G14: 2.24 | H14: =G14/F14*100 | I14: =IFERROR((G14/F14)/(SUMIFS($G$3:$G$98,$A$3:$A$98,A14,$B$3:$B$98,0)/SUMIFS($F$3:$F$98,$A$3:$A$98,A14,$B$3:$B$98,0)),"") | J14: =IF(B14=0,1,IF(C14<=1,G14-SUMIFS($G$3:$G$98,$A$3:$A$98,A14,$B$3:$B$98,0),G14-G13)/E14/(SUMIFS($G$3:$G$98,$A$3:$A$98,A14,$B$3:$B$98,0)/SUMIFS($F$3:$F$98,$A$3:$A$98,A14,$B$3:$B$98,0))) | K14: 0.201 | L14: 0.324 | M14: =IF(OR(K14="",L14="",L14=0),"",K14/L14) | O14: =IF(B14=0,"基准",IF(AND(N14<>"",I14<0.85),"功能型：单看输出偏低属正常",IF(I14>=0.85,"划算",IF(I14>=0.65,"略亏：空位紧张时仍值得","偏亏：建议降价或加强"))))
A15: dart | B15: 3 | C15: 2 | D15: 精准 | E15: 100 | F15: 250 | G15: 2.54 | H15: =G15/F15*100 | I15: =IFERROR((G15/F15)/(SUMIFS($G$3:$G$98,$A$3:$A$98,A15,$B$3:$B$98,0)/SUMIFS($F$3:$F$98,$A$3:$A$98,A15,$B$3:$B$98,0)),"") | J15: =IF(B15=0,1,IF(C15<=1,G15-SUMIFS($G$3:$G$98,$A$3:$A$98,A15,$B$3:$B$98,0),G15-G14)/E15/(SUMIFS($G$3:$G$98,$A$3:$A$98,A15,$B$3:$B$98,0)/SUMIFS($F$3:$F$98,$A$3:$A$98,A15,$B$3:$B$98,0))) | K15: 0.281 | L15: 0.497 | M15: =IF(OR(K15="",L15="",L15=0),"",K15/L15) | O15: =IF(B15=0,"基准",IF(AND(N15<>"",I15<0.85),"功能型：单看输出偏低属正常",IF(I15>=0.85,"划算",IF(I15>=0.65,"略亏：空位紧张时仍值得","偏亏：建议降价或加强"))))
A16: dart | B16: 3 | C16: 3 | D16: 汽水黏鞋 | E16: 300 | F16: 550 | G16: 2.54 | H16: =G16/F16*100 | I16: =IFERROR((G16/F16)/(SUMIFS($G$3:$G$98,$A$3:$A$98,A16,$B$3:$B$98,0)/SUMIFS($F$3:$F$98,$A$3:$A$98,A16,$B$3:$B$98,0)),"") | J16: =IF(B16=0,1,IF(C16<=1,G16-SUMIFS($G$3:$G$98,$A$3:$A$98,A16,$B$3:$B$98,0),G16-G15)/E16/(SUMIFS($G$3:$G$98,$A$3:$A$98,A16,$B$3:$B$98,0)/SUMIFS($F$3:$F$98,$A$3:$A$98,A16,$B$3:$B$98,0))) | K16: 0.271 | L16: 0.795 | M16: =IF(OR(K16="",L16="",L16=0),"",K16/L16) | N16: 标记增伤 | O16: =IF(B16=0,"基准",IF(AND(N16<>"",I16<0.85),"功能型：单看输出偏低属正常",IF(I16>=0.85,"划算",IF(I16>=0.65,"略亏：空位紧张时仍值得","偏亏：建议降价或加强"))))
A17: dart | B17: 3 | C17: 4 | D17: 远程狙罐 | E17: 700 | F17: 1250 | G17: 3.08 | H17: =G17/F17*100 | I17: =IFERROR((G17/F17)/(SUMIFS($G$3:$G$98,$A$3:$A$98,A17,$B$3:$B$98,0)/SUMIFS($F$3:$F$98,$A$3:$A$98,A17,$B$3:$B$98,0)),"") | J17: =IF(B17=0,1,IF(C17<=1,G17-SUMIFS($G$3:$G$98,$A$3:$A$98,A17,$B$3:$B$98,0),G17-G16)/E17/(SUMIFS($G$3:$G$98,$A$3:$A$98,A17,$B$3:$B$98,0)/SUMIFS($F$3:$F$98,$A$3:$A$98,A17,$B$3:$B$98,0))) | K17: 0.36 | L17: 1 | M17: =IF(OR(K17="",L17="",L17=0),"",K17/L17) | O17: =IF(B17=0,"基准",IF(AND(N17<>"",I17<0.85),"功能型：单看输出偏低属正常",IF(I17>=0.85,"划算",IF(I17>=0.65,"略亏：空位紧张时仍值得","偏亏：建议降价或加强"))))
A18: dart | B18: 3 | C18: 5 | D18: 补给站站长 | E18: 1300 | F18: 2550 | G18: 3.08 | H18: =G18/F18*100 | I18: =IFERROR((G18/F18)/(SUMIFS($G$3:$G$98,$A$3:$A$98,A18,$B$3:$B$98,0)/SUMIFS($F$3:$F$98,$A$3:$A$98,A18,$B$3:$B$98,0)),"") | J18: =IF(B18=0,1,IF(C18<=1,G18-SUMIFS($G$3:$G$98,$A$3:$A$98,A18,$B$3:$B$98,0),G18-G17)/E18/(SUMIFS($G$3:$G$98,$A$3:$A$98,A18,$B$3:$B$98,0)/SUMIFS($F$3:$F$98,$A$3:$A$98,A18,$B$3:$B$98,0))) | M18: =IF(OR(K18="",L18="",L18=0),"",K18/L18) | N18: 光环 | O18: =IF(B18=0,"基准",IF(AND(N18<>"",I18<0.85),"功能型：单看输出偏低属正常",IF(I18>=0.85,"划算",IF(I18>=0.65,"略亏：空位紧张时仍值得","偏亏：建议降价或加强"))))
A19: bomb | B19: 0 | C19: 0 | D19: 基础 | E19: 160 | F19: 160 | G19: 10.54 | H19: =G19/F19*100 | I19: =IFERROR((G19/F19)/(SUMIFS($G$3:$G$98,$A$3:$A$98,A19,$B$3:$B$98,0)/SUMIFS($F$3:$F$98,$A$3:$A$98,A19,$B$3:$B$98,0)),"") | J19: =IF(B19=0,1,IF(C19<=1,G19-SUMIFS($G$3:$G$98,$A$3:$A$98,A19,$B$3:$B$98,0),G19-G18)/E19/(SUMIFS($G$3:$G$98,$A$3:$A$98,A19,$B$3:$B$98,0)/SUMIFS($F$3:$F$98,$A$3:$A$98,A19,$B$3:$B$98,0))) | M19: =IF(OR(K19="",L19="",L19=0),"",K19/L19) | O19: =IF(B19=0,"基准",IF(AND(N19<>"",I19<0.85),"功能型：单看输出偏低属正常",IF(I19>=0.85,"划算",IF(I19>=0.65,"略亏：空位紧张时仍值得","偏亏：建议降价或加强"))))
A20: bomb | B20: 1 | C20: 1 | D20: 大片香蕉皮 | E20: 70 | F20: 230 | G20: 12.53 | H20: =G20/F20*100 | I20: =IFERROR((G20/F20)/(SUMIFS($G$3:$G$98,$A$3:$A$98,A20,$B$3:$B$98,0)/SUMIFS($F$3:$F$98,$A$3:$A$98,A20,$B$3:$B$98,0)),"") | J20: =IF(B20=0,1,IF(C20<=1,G20-SUMIFS($G$3:$G$98,$A$3:$A$98,A20,$B$3:$B$98,0),G20-G19)/E20/(SUMIFS($G$3:$G$98,$A$3:$A$98,A20,$B$3:$B$98,0)/SUMIFS($F$3:$F$98,$A$3:$A$98,A20,$B$3:$B$98,0))) | K20: 0.394 | L20: 0.301 | M20: =IF(OR(K20="",L20="",L20=0),"",K20/L20) | O20: =IF(B20=0,"基准",IF(AND(N20<>"",I20<0.85),"功能型：单看输出偏低属正常",IF(I20>=0.85,"划算",IF(I20>=0.65,"略亏：空位紧张时仍值得","偏亏：建议降价或加强"))))
A21: bomb | B21: 1 | C21: 2 | D21: 熟透香蕉 | E21: 150 | F21: 380 | G21: 25.05 | H21: =G21/F21*100 | I21: =IFERROR((G21/F21)/(SUMIFS($G$3:$G$98,$A$3:$A$98,A21,$B$3:$B$98,0)/SUMIFS($F$3:$F$98,$A$3:$A$98,A21,$B$3:$B$98,0)),"") | J21: =IF(B21=0,1,IF(C21<=1,G21-SUMIFS($G$3:$G$98,$A$3:$A$98,A21,$B$3:$B$98,0),G21-G20)/E21/(SUMIFS($G$3:$G$98,$A$3:$A$98,A21,$B$3:$B$98,0)/SUMIFS($F$3:$F$98,$A$3:$A$98,A21,$B$3:$B$98,0))) | K21: 0.452 | L21: 0.489 | M21: =IF(OR(K21="",L21="",L21=0),"",K21/L21) | O21: =IF(B21=0,"基准",IF(AND(N21<>"",I21<0.85),"功能型：单看输出偏低属正常",IF(I21>=0.85,"划算",IF(I21>=0.65,"略亏：空位紧张时仍值得","偏亏：建议降价或加强"))))
